[2022-05-03 22:08:23 +0800] [10] [INFO] Starting gunicorn 20.1.0
[2022-05-03 22:08:23 +0800] [10] [INFO] Listening at: http://0.0.0.0:8000 (10)
[2022-05-03 22:08:23 +0800] [10] [INFO] Using worker: gevent
[2022-05-03 22:08:23 +0800] [13] [INFO] Booting worker with pid: 13
[2022-05-03 22:08:23 +0800] [13] [ERROR] Exception in worker process
Traceback (most recent call last):
  File "/usr/local/lib/python3.7/site-packages/gunicorn/arbiter.py", line 589, in spawn_worker
    worker.init_process()
  File "/usr/local/lib/python3.7/site-packages/gunicorn/workers/ggevent.py", line 146, in init_process
    super().init_process()
  File "/usr/local/lib/python3.7/site-packages/gunicorn/workers/base.py", line 134, in init_process
    self.load_wsgi()
  File "/usr/local/lib/python3.7/site-packages/gunicorn/workers/base.py", line 146, in load_wsgi
    self.wsgi = self.app.wsgi()
  File "/usr/local/lib/python3.7/site-packages/gunicorn/app/base.py", line 67, in wsgi
    self.callable = self.load()
  File "/usr/local/lib/python3.7/site-packages/gunicorn/app/wsgiapp.py", line 58, in load
    return self.load_wsgiapp()
  File "/usr/local/lib/python3.7/site-packages/gunicorn/app/wsgiapp.py", line 48, in load_wsgiapp
    return util.import_app(self.app_uri)
  File "/usr/local/lib/python3.7/site-packages/gunicorn/util.py", line 359, in import_app
    mod = importlib.import_module(module)
  File "/usr/local/lib/python3.7/importlib/__init__.py", line 127, in import_module
    return _bootstrap._gcd_import(name[level:], package, level)
  File "<frozen importlib._bootstrap>", line 1006, in _gcd_import
  File "<frozen importlib._bootstrap>", line 983, in _find_and_load
  File "<frozen importlib._bootstrap>", line 965, in _find_and_load_unlocked
ModuleNotFoundError: No module named 'wsgi'
[2022-05-03 22:08:23 +0800] [13] [INFO] Worker exiting (pid: 13)
[2022-05-03 22:08:23 +0800] [14] [INFO] Booting worker with pid: 14
[2022-05-03 22:08:23 +0800] [14] [ERROR] Exception in worker process
Traceback (most recent call last):
  File "/usr/local/lib/python3.7/site-packages/gunicorn/arbiter.py", line 589, in spawn_worker
    worker.init_process()
  File "/usr/local/lib/python3.7/site-packages/gunicorn/workers/ggevent.py", line 146, in init_process
    super().init_process()
  File "/usr/local/lib/python3.7/site-packages/gunicorn/workers/base.py", line 134, in init_process
    self.load_wsgi()
  File "/usr/local/lib/python3.7/site-packages/gunicorn/workers/base.py", line 146, in load_wsgi
    self.wsgi = self.app.wsgi()
  File "/usr/local/lib/python3.7/site-packages/gunicorn/app/base.py", line 67, in wsgi
    self.callable = self.load()
  File "/usr/local/lib/python3.7/site-packages/gunicorn/app/wsgiapp.py", line 58, in load
    return self.load_wsgiapp()
  File "/usr/local/lib/python3.7/site-packages/gunicorn/app/wsgiapp.py", line 48, in load_wsgiapp
    return util.import_app(self.app_uri)
  File "/usr/local/lib/python3.7/site-packages/gunicorn/util.py", line 359, in import_app
    mod = importlib.import_module(module)
  File "/usr/local/lib/python3.7/importlib/__init__.py", line 127, in import_module
    return _bootstrap._gcd_import(name[level:], package, level)
  File "<frozen importlib._bootstrap>", line 1006, in _gcd_import
  File "<frozen importlib._bootstrap>", line 983, in _find_and_load
  File "<frozen importlib._bootstrap>", line 965, in _find_and_load_unlocked
ModuleNotFoundError: No module named 'wsgi'
[2022-05-03 22:08:23 +0800] [14] [INFO] Worker exiting (pid: 14)
Traceback (most recent call last):
  File "/usr/local/lib/python3.7/site-packages/gunicorn/arbiter.py", line 202, in run
    self.manage_workers()
  File "/usr/local/lib/python3.7/site-packages/gunicorn/arbiter.py", line 551, in manage_workers
    self.spawn_workers()
  File "/usr/local/lib/python3.7/site-packages/gunicorn/arbiter.py", line 623, in spawn_workers
    time.sleep(0.1 * random.random())
  File "/usr/local/lib/python3.7/site-packages/gunicorn/arbiter.py", line 242, in handle_chld
    self.reap_workers()
  File "/usr/local/lib/python3.7/site-packages/gunicorn/arbiter.py", line 525, in reap_workers
    raise HaltServer(reason, self.WORKER_BOOT_ERROR)
gunicorn.errors.HaltServer: <HaltServer 'Worker failed to boot.' 3>

During handling of the above exception, another exception occurred:

Traceback (most recent call last):
  File "/usr/local/bin/gunicorn", line 8, in <module>
    sys.exit(run())
  File "/usr/local/lib/python3.7/site-packages/gunicorn/app/wsgiapp.py", line 67, in run
    WSGIApplication("%(prog)s [OPTIONS] [APP_MODULE]").run()
  File "/usr/local/lib/python3.7/site-packages/gunicorn/app/base.py", line 231, in run
    super().run()
  File "/usr/local/lib/python3.7/site-packages/gunicorn/app/base.py", line 72, in run
    Arbiter(self).run()
  File "/usr/local/lib/python3.7/site-packages/gunicorn/arbiter.py", line 229, in run
    self.halt(reason=inst.reason, exit_status=inst.exit_status)
  File "/usr/local/lib/python3.7/site-packages/gunicorn/arbiter.py", line 342, in halt
    self.stop()
  File "/usr/local/lib/python3.7/site-packages/gunicorn/arbiter.py", line 393, in stop
    time.sleep(0.1)
  File "/usr/local/lib/python3.7/site-packages/gunicorn/arbiter.py", line 242, in handle_chld
    self.reap_workers()
  File "/usr/local/lib/python3.7/site-packages/gunicorn/arbiter.py", line 525, in reap_workers
    raise HaltServer(reason, self.WORKER_BOOT_ERROR)
gunicorn.errors.HaltServer: <HaltServer 'Worker failed to boot.' 3>
[2022-05-03 22:08:24 +0800] [15] [INFO] Starting gunicorn 20.1.0
[2022-05-03 22:08:24 +0800] [15] [INFO] Listening at: http://0.0.0.0:8000 (15)
[2022-05-03 22:08:24 +0800] [15] [INFO] Using worker: gevent
[2022-05-03 22:08:24 +0800] [18] [INFO] Booting worker with pid: 18
[2022-05-03 22:08:24 +0800] [18] [ERROR] Exception in worker process
Traceback (most recent call last):
  File "/usr/local/lib/python3.7/site-packages/gunicorn/arbiter.py", line 589, in spawn_worker
    worker.init_process()
  File "/usr/local/lib/python3.7/site-packages/gunicorn/workers/ggevent.py", line 146, in init_process
    super().init_process()
  File "/usr/local/lib/python3.7/site-packages/gunicorn/workers/base.py", line 134, in init_process
    self.load_wsgi()
  File "/usr/local/lib/python3.7/site-packages/gunicorn/workers/base.py", line 146, in load_wsgi
    self.wsgi = self.app.wsgi()
  File "/usr/local/lib/python3.7/site-packages/gunicorn/app/base.py", line 67, in wsgi
    self.callable = self.load()
  File "/usr/local/lib/python3.7/site-packages/gunicorn/app/wsgiapp.py", line 58, in load
    return self.load_wsgiapp()
  File "/usr/local/lib/python3.7/site-packages/gunicorn/app/wsgiapp.py", line 48, in load_wsgiapp
    return util.import_app(self.app_uri)
  File "/usr/local/lib/python3.7/site-packages/gunicorn/util.py", line 359, in import_app
    mod = importlib.import_module(module)
  File "/usr/local/lib/python3.7/importlib/__init__.py", line 127, in import_module
    return _bootstrap._gcd_import(name[level:], package, level)
  File "<frozen importlib._bootstrap>", line 1006, in _gcd_import
  File "<frozen importlib._bootstrap>", line 983, in _find_and_load
  File "<frozen importlib._bootstrap>", line 965, in _find_and_load_unlocked
ModuleNotFoundError: No module named 'wsgi'
[2022-05-03 22:08:24 +0800] [18] [INFO] Worker exiting (pid: 18)
[2022-05-03 22:08:24 +0800] [15] [INFO] Shutting down: Master
[2022-05-03 22:08:24 +0800] [15] [INFO] Reason: Worker failed to boot.
[2022-05-03 22:08:26 +0800] [19] [INFO] Starting gunicorn 20.1.0
[2022-05-03 22:08:26 +0800] [19] [INFO] Listening at: http://0.0.0.0:8000 (19)
[2022-05-03 22:08:26 +0800] [19] [INFO] Using worker: gevent
[2022-05-03 22:08:26 +0800] [22] [INFO] Booting worker with pid: 22
[2022-05-03 22:08:26 +0800] [22] [ERROR] Exception in worker process
Traceback (most recent call last):
  File "/usr/local/lib/python3.7/site-packages/gunicorn/arbiter.py", line 589, in spawn_worker
    worker.init_process()
  File "/usr/local/lib/python3.7/site-packages/gunicorn/workers/ggevent.py", line 146, in init_process
    super().init_process()
  File "/usr/local/lib/python3.7/site-packages/gunicorn/workers/base.py", line 134, in init_process
    self.load_wsgi()
  File "/usr/local/lib/python3.7/site-packages/gunicorn/workers/base.py", line 146, in load_wsgi
    self.wsgi = self.app.wsgi()
  File "/usr/local/lib/python3.7/site-packages/gunicorn/app/base.py", line 67, in wsgi
    self.callable = self.load()
  File "/usr/local/lib/python3.7/site-packages/gunicorn/app/wsgiapp.py", line 58, in load
    return self.load_wsgiapp()
  File "/usr/local/lib/python3.7/site-packages/gunicorn/app/wsgiapp.py", line 48, in load_wsgiapp
    return util.import_app(self.app_uri)
  File "/usr/local/lib/python3.7/site-packages/gunicorn/util.py", line 359, in import_app
    mod = importlib.import_module(module)
  File "/usr/local/lib/python3.7/importlib/__init__.py", line 127, in import_module
    return _bootstrap._gcd_import(name[level:], package, level)
  File "<frozen importlib._bootstrap>", line 1006, in _gcd_import
  File "<frozen importlib._bootstrap>", line 983, in _find_and_load
  File "<frozen importlib._bootstrap>", line 965, in _find_and_load_unlocked
ModuleNotFoundError: No module named 'wsgi'
[2022-05-03 22:08:26 +0800] [22] [INFO] Worker exiting (pid: 22)
[2022-05-03 22:08:26 +0800] [23] [INFO] Booting worker with pid: 23
[2022-05-03 22:08:26 +0800] [23] [ERROR] Exception in worker process
Traceback (most recent call last):
  File "/usr/local/lib/python3.7/site-packages/gunicorn/arbiter.py", line 589, in spawn_worker
    worker.init_process()
  File "/usr/local/lib/python3.7/site-packages/gunicorn/workers/ggevent.py", line 146, in init_process
    super().init_process()
  File "/usr/local/lib/python3.7/site-packages/gunicorn/workers/base.py", line 134, in init_process
    self.load_wsgi()
  File "/usr/local/lib/python3.7/site-packages/gunicorn/workers/base.py", line 146, in load_wsgi
    self.wsgi = self.app.wsgi()
  File "/usr/local/lib/python3.7/site-packages/gunicorn/app/base.py", line 67, in wsgi
    self.callable = self.load()
  File "/usr/local/lib/python3.7/site-packages/gunicorn/app/wsgiapp.py", line 58, in load
    return self.load_wsgiapp()
  File "/usr/local/lib/python3.7/site-packages/gunicorn/app/wsgiapp.py", line 48, in load_wsgiapp
    return util.import_app(self.app_uri)
  File "/usr/local/lib/python3.7/site-packages/gunicorn/util.py", line 359, in import_app
    mod = importlib.import_module(module)
  File "/usr/local/lib/python3.7/importlib/__init__.py", line 127, in import_module
    return _bootstrap._gcd_import(name[level:], package, level)
  File "<frozen importlib._bootstrap>", line 1006, in _gcd_import
  File "<frozen importlib._bootstrap>", line 983, in _find_and_load
  File "<frozen importlib._bootstrap>", line 965, in _find_and_load_unlocked
ModuleNotFoundError: No module named 'wsgi'
[2022-05-03 22:08:26 +0800] [23] [INFO] Worker exiting (pid: 23)
Traceback (most recent call last):
  File "/usr/local/lib/python3.7/site-packages/gunicorn/arbiter.py", line 202, in run
    self.manage_workers()
  File "/usr/local/lib/python3.7/site-packages/gunicorn/arbiter.py", line 551, in manage_workers
    self.spawn_workers()
  File "/usr/local/lib/python3.7/site-packages/gunicorn/arbiter.py", line 623, in spawn_workers
    time.sleep(0.1 * random.random())
  File "/usr/local/lib/python3.7/site-packages/gunicorn/arbiter.py", line 242, in handle_chld
    self.reap_workers()
  File "/usr/local/lib/python3.7/site-packages/gunicorn/arbiter.py", line 525, in reap_workers
    raise HaltServer(reason, self.WORKER_BOOT_ERROR)
gunicorn.errors.HaltServer: <HaltServer 'Worker failed to boot.' 3>

During handling of the above exception, another exception occurred:

Traceback (most recent call last):
  File "/usr/local/bin/gunicorn", line 8, in <module>
    sys.exit(run())
  File "/usr/local/lib/python3.7/site-packages/gunicorn/app/wsgiapp.py", line 67, in run
    WSGIApplication("%(prog)s [OPTIONS] [APP_MODULE]").run()
  File "/usr/local/lib/python3.7/site-packages/gunicorn/app/base.py", line 231, in run
    super().run()
  File "/usr/local/lib/python3.7/site-packages/gunicorn/app/base.py", line 72, in run
    Arbiter(self).run()
  File "/usr/local/lib/python3.7/site-packages/gunicorn/arbiter.py", line 229, in run
    self.halt(reason=inst.reason, exit_status=inst.exit_status)
  File "/usr/local/lib/python3.7/site-packages/gunicorn/arbiter.py", line 342, in halt
    self.stop()
  File "/usr/local/lib/python3.7/site-packages/gunicorn/arbiter.py", line 393, in stop
    time.sleep(0.1)
  File "/usr/local/lib/python3.7/site-packages/gunicorn/arbiter.py", line 242, in handle_chld
    self.reap_workers()
  File "/usr/local/lib/python3.7/site-packages/gunicorn/arbiter.py", line 525, in reap_workers
    raise HaltServer(reason, self.WORKER_BOOT_ERROR)
gunicorn.errors.HaltServer: <HaltServer 'Worker failed to boot.' 3>
[2022-05-03 22:08:29 +0800] [24] [INFO] Starting gunicorn 20.1.0
[2022-05-03 22:08:29 +0800] [24] [INFO] Listening at: http://0.0.0.0:8000 (24)
[2022-05-03 22:08:29 +0800] [24] [INFO] Using worker: gevent
[2022-05-03 22:08:29 +0800] [27] [INFO] Booting worker with pid: 27
[2022-05-03 22:08:29 +0800] [28] [INFO] Booting worker with pid: 28
[2022-05-03 22:08:29 +0800] [27] [ERROR] Exception in worker process
Traceback (most recent call last):
  File "/usr/local/lib/python3.7/site-packages/gunicorn/arbiter.py", line 589, in spawn_worker
    worker.init_process()
  File "/usr/local/lib/python3.7/site-packages/gunicorn/workers/ggevent.py", line 146, in init_process
    super().init_process()
  File "/usr/local/lib/python3.7/site-packages/gunicorn/workers/base.py", line 134, in init_process
    self.load_wsgi()
  File "/usr/local/lib/python3.7/site-packages/gunicorn/workers/base.py", line 146, in load_wsgi
    self.wsgi = self.app.wsgi()
  File "/usr/local/lib/python3.7/site-packages/gunicorn/app/base.py", line 67, in wsgi
    self.callable = self.load()
  File "/usr/local/lib/python3.7/site-packages/gunicorn/app/wsgiapp.py", line 58, in load
    return self.load_wsgiapp()
  File "/usr/local/lib/python3.7/site-packages/gunicorn/app/wsgiapp.py", line 48, in load_wsgiapp
    return util.import_app(self.app_uri)
  File "/usr/local/lib/python3.7/site-packages/gunicorn/util.py", line 359, in import_app
    mod = importlib.import_module(module)
  File "/usr/local/lib/python3.7/importlib/__init__.py", line 127, in import_module
    return _bootstrap._gcd_import(name[level:], package, level)
  File "<frozen importlib._bootstrap>", line 1006, in _gcd_import
  File "<frozen importlib._bootstrap>", line 983, in _find_and_load
  File "<frozen importlib._bootstrap>", line 965, in _find_and_load_unlocked
ModuleNotFoundError: No module named 'wsgi'
[2022-05-03 22:08:29 +0800] [27] [INFO] Worker exiting (pid: 27)
[2022-05-03 22:08:29 +0800] [28] [ERROR] Exception in worker process
Traceback (most recent call last):
  File "/usr/local/lib/python3.7/site-packages/gunicorn/arbiter.py", line 589, in spawn_worker
    worker.init_process()
  File "/usr/local/lib/python3.7/site-packages/gunicorn/workers/ggevent.py", line 146, in init_process
    super().init_process()
  File "/usr/local/lib/python3.7/site-packages/gunicorn/workers/base.py", line 134, in init_process
    self.load_wsgi()
  File "/usr/local/lib/python3.7/site-packages/gunicorn/workers/base.py", line 146, in load_wsgi
    self.wsgi = self.app.wsgi()
  File "/usr/local/lib/python3.7/site-packages/gunicorn/app/base.py", line 67, in wsgi
    self.callable = self.load()
  File "/usr/local/lib/python3.7/site-packages/gunicorn/app/wsgiapp.py", line 58, in load
    return self.load_wsgiapp()
  File "/usr/local/lib/python3.7/site-packages/gunicorn/app/wsgiapp.py", line 48, in load_wsgiapp
    return util.import_app(self.app_uri)
  File "/usr/local/lib/python3.7/site-packages/gunicorn/util.py", line 359, in import_app
    mod = importlib.import_module(module)
  File "/usr/local/lib/python3.7/importlib/__init__.py", line 127, in import_module
    return _bootstrap._gcd_import(name[level:], package, level)
  File "<frozen importlib._bootstrap>", line 1006, in _gcd_import
  File "<frozen importlib._bootstrap>", line 983, in _find_and_load
  File "<frozen importlib._bootstrap>", line 965, in _find_and_load_unlocked
ModuleNotFoundError: No module named 'wsgi'
[2022-05-03 22:08:29 +0800] [28] [INFO] Worker exiting (pid: 28)
Traceback (most recent call last):
  File "/usr/local/lib/python3.7/site-packages/gunicorn/arbiter.py", line 202, in run
    self.manage_workers()
  File "/usr/local/lib/python3.7/site-packages/gunicorn/arbiter.py", line 551, in manage_workers
    self.spawn_workers()
  File "/usr/local/lib/python3.7/site-packages/gunicorn/arbiter.py", line 623, in spawn_workers
    time.sleep(0.1 * random.random())
  File "/usr/local/lib/python3.7/site-packages/gunicorn/arbiter.py", line 242, in handle_chld
    self.reap_workers()
  File "/usr/local/lib/python3.7/site-packages/gunicorn/arbiter.py", line 525, in reap_workers
    raise HaltServer(reason, self.WORKER_BOOT_ERROR)
gunicorn.errors.HaltServer: <HaltServer 'Worker failed to boot.' 3>

During handling of the above exception, another exception occurred:

Traceback (most recent call last):
  File "/usr/local/bin/gunicorn", line 8, in <module>
    sys.exit(run())
  File "/usr/local/lib/python3.7/site-packages/gunicorn/app/wsgiapp.py", line 67, in run
    WSGIApplication("%(prog)s [OPTIONS] [APP_MODULE]").run()
  File "/usr/local/lib/python3.7/site-packages/gunicorn/app/base.py", line 231, in run
    super().run()
  File "/usr/local/lib/python3.7/site-packages/gunicorn/app/base.py", line 72, in run
    Arbiter(self).run()
  File "/usr/local/lib/python3.7/site-packages/gunicorn/arbiter.py", line 229, in run
    self.halt(reason=inst.reason, exit_status=inst.exit_status)
  File "/usr/local/lib/python3.7/site-packages/gunicorn/arbiter.py", line 342, in halt
    self.stop()
  File "/usr/local/lib/python3.7/site-packages/gunicorn/arbiter.py", line 393, in stop
    time.sleep(0.1)
  File "/usr/local/lib/python3.7/site-packages/gunicorn/arbiter.py", line 242, in handle_chld
    self.reap_workers()
  File "/usr/local/lib/python3.7/site-packages/gunicorn/arbiter.py", line 525, in reap_workers
    raise HaltServer(reason, self.WORKER_BOOT_ERROR)
gunicorn.errors.HaltServer: <HaltServer 'Worker failed to boot.' 3>
[2022-05-03 22:08:34 +0800] [29] [INFO] Starting gunicorn 20.1.0
[2022-05-03 22:08:34 +0800] [29] [INFO] Listening at: http://0.0.0.0:8000 (29)
[2022-05-03 22:08:34 +0800] [29] [INFO] Using worker: gevent
[2022-05-03 22:08:34 +0800] [32] [INFO] Booting worker with pid: 32
[2022-05-03 22:08:34 +0800] [33] [INFO] Booting worker with pid: 33
[2022-05-03 22:08:34 +0800] [32] [ERROR] Exception in worker process
Traceback (most recent call last):
  File "/usr/local/lib/python3.7/site-packages/gunicorn/arbiter.py", line 589, in spawn_worker
    worker.init_process()
  File "/usr/local/lib/python3.7/site-packages/gunicorn/workers/ggevent.py", line 146, in init_process
    super().init_process()
  File "/usr/local/lib/python3.7/site-packages/gunicorn/workers/base.py", line 134, in init_process
    self.load_wsgi()
  File "/usr/local/lib/python3.7/site-packages/gunicorn/workers/base.py", line 146, in load_wsgi
    self.wsgi = self.app.wsgi()
  File "/usr/local/lib/python3.7/site-packages/gunicorn/app/base.py", line 67, in wsgi
    self.callable = self.load()
  File "/usr/local/lib/python3.7/site-packages/gunicorn/app/wsgiapp.py", line 58, in load
    return self.load_wsgiapp()
  File "/usr/local/lib/python3.7/site-packages/gunicorn/app/wsgiapp.py", line 48, in load_wsgiapp
    return util.import_app(self.app_uri)
  File "/usr/local/lib/python3.7/site-packages/gunicorn/util.py", line 359, in import_app
    mod = importlib.import_module(module)
  File "/usr/local/lib/python3.7/importlib/__init__.py", line 127, in import_module
    return _bootstrap._gcd_import(name[level:], package, level)
  File "<frozen importlib._bootstrap>", line 1006, in _gcd_import
  File "<frozen importlib._bootstrap>", line 983, in _find_and_load
  File "<frozen importlib._bootstrap>", line 965, in _find_and_load_unlocked
ModuleNotFoundError: No module named 'wsgi'
[2022-05-03 22:08:34 +0800] [32] [INFO] Worker exiting (pid: 32)
[2022-05-03 22:08:34 +0800] [33] [ERROR] Exception in worker process
Traceback (most recent call last):
  File "/usr/local/lib/python3.7/site-packages/gunicorn/arbiter.py", line 589, in spawn_worker
    worker.init_process()
  File "/usr/local/lib/python3.7/site-packages/gunicorn/workers/ggevent.py", line 146, in init_process
    super().init_process()
  File "/usr/local/lib/python3.7/site-packages/gunicorn/workers/base.py", line 134, in init_process
    self.load_wsgi()
  File "/usr/local/lib/python3.7/site-packages/gunicorn/workers/base.py", line 146, in load_wsgi
    self.wsgi = self.app.wsgi()
  File "/usr/local/lib/python3.7/site-packages/gunicorn/app/base.py", line 67, in wsgi
    self.callable = self.load()
  File "/usr/local/lib/python3.7/site-packages/gunicorn/app/wsgiapp.py", line 58, in load
    return self.load_wsgiapp()
  File "/usr/local/lib/python3.7/site-packages/gunicorn/app/wsgiapp.py", line 48, in load_wsgiapp
    return util.import_app(self.app_uri)
  File "/usr/local/lib/python3.7/site-packages/gunicorn/util.py", line 359, in import_app
    mod = importlib.import_module(module)
  File "/usr/local/lib/python3.7/importlib/__init__.py", line 127, in import_module
    return _bootstrap._gcd_import(name[level:], package, level)
  File "<frozen importlib._bootstrap>", line 1006, in _gcd_import
  File "<frozen importlib._bootstrap>", line 983, in _find_and_load
  File "<frozen importlib._bootstrap>", line 965, in _find_and_load_unlocked
ModuleNotFoundError: No module named 'wsgi'
[2022-05-03 22:08:34 +0800] [33] [INFO] Worker exiting (pid: 33)
[2022-05-03 22:08:34 +0800] [29] [WARNING] Worker with pid 33 was terminated due to signal 15
[2022-05-03 22:08:34 +0800] [29] [INFO] Shutting down: Master
[2022-05-03 22:08:34 +0800] [29] [INFO] Reason: Worker failed to boot.
[2022-05-03 22:08:39 +0800] [34] [INFO] Starting gunicorn 20.1.0
[2022-05-03 22:08:39 +0800] [34] [INFO] Listening at: http://0.0.0.0:8000 (34)
[2022-05-03 22:08:39 +0800] [34] [INFO] Using worker: gevent
[2022-05-03 22:08:39 +0800] [37] [INFO] Booting worker with pid: 37
[2022-05-03 22:08:39 +0800] [37] [ERROR] Exception in worker process
Traceback (most recent call last):
  File "/usr/local/lib/python3.7/site-packages/gunicorn/arbiter.py", line 589, in spawn_worker
    worker.init_process()
  File "/usr/local/lib/python3.7/site-packages/gunicorn/workers/ggevent.py", line 146, in init_process
    super().init_process()
  File "/usr/local/lib/python3.7/site-packages/gunicorn/workers/base.py", line 134, in init_process
    self.load_wsgi()
  File "/usr/local/lib/python3.7/site-packages/gunicorn/workers/base.py", line 146, in load_wsgi
    self.wsgi = self.app.wsgi()
  File "/usr/local/lib/python3.7/site-packages/gunicorn/app/base.py", line 67, in wsgi
    self.callable = self.load()
  File "/usr/local/lib/python3.7/site-packages/gunicorn/app/wsgiapp.py", line 58, in load
    return self.load_wsgiapp()
  File "/usr/local/lib/python3.7/site-packages/gunicorn/app/wsgiapp.py", line 48, in load_wsgiapp
    return util.import_app(self.app_uri)
  File "/usr/local/lib/python3.7/site-packages/gunicorn/util.py", line 359, in import_app
    mod = importlib.import_module(module)
  File "/usr/local/lib/python3.7/importlib/__init__.py", line 127, in import_module
    return _bootstrap._gcd_import(name[level:], package, level)
  File "<frozen importlib._bootstrap>", line 1006, in _gcd_import
  File "<frozen importlib._bootstrap>", line 983, in _find_and_load
  File "<frozen importlib._bootstrap>", line 965, in _find_and_load_unlocked
ModuleNotFoundError: No module named 'wsgi'
[2022-05-03 22:08:39 +0800] [37] [INFO] Worker exiting (pid: 37)
[2022-05-03 22:08:39 +0800] [34] [INFO] Shutting down: Master
[2022-05-03 22:08:39 +0800] [34] [INFO] Reason: Worker failed to boot.
[2022-05-03 22:08:45 +0800] [38] [INFO] Starting gunicorn 20.1.0
[2022-05-03 22:08:45 +0800] [38] [INFO] Listening at: http://0.0.0.0:8000 (38)
[2022-05-03 22:08:45 +0800] [38] [INFO] Using worker: gevent
[2022-05-03 22:08:45 +0800] [41] [INFO] Booting worker with pid: 41
[2022-05-03 22:08:45 +0800] [41] [ERROR] Exception in worker process
Traceback (most recent call last):
  File "/usr/local/lib/python3.7/site-packages/gunicorn/arbiter.py", line 589, in spawn_worker
    worker.init_process()
  File "/usr/local/lib/python3.7/site-packages/gunicorn/workers/ggevent.py", line 146, in init_process
    super().init_process()
  File "/usr/local/lib/python3.7/site-packages/gunicorn/workers/base.py", line 134, in init_process
    self.load_wsgi()
  File "/usr/local/lib/python3.7/site-packages/gunicorn/workers/base.py", line 146, in load_wsgi
    self.wsgi = self.app.wsgi()
  File "/usr/local/lib/python3.7/site-packages/gunicorn/app/base.py", line 67, in wsgi
    self.callable = self.load()
  File "/usr/local/lib/python3.7/site-packages/gunicorn/app/wsgiapp.py", line 58, in load
    return self.load_wsgiapp()
  File "/usr/local/lib/python3.7/site-packages/gunicorn/app/wsgiapp.py", line 48, in load_wsgiapp
    return util.import_app(self.app_uri)
  File "/usr/local/lib/python3.7/site-packages/gunicorn/util.py", line 359, in import_app
    mod = importlib.import_module(module)
  File "/usr/local/lib/python3.7/importlib/__init__.py", line 127, in import_module
    return _bootstrap._gcd_import(name[level:], package, level)
  File "<frozen importlib._bootstrap>", line 1006, in _gcd_import
  File "<frozen importlib._bootstrap>", line 983, in _find_and_load
  File "<frozen importlib._bootstrap>", line 965, in _find_and_load_unlocked
ModuleNotFoundError: No module named 'wsgi'
[2022-05-03 22:08:45 +0800] [41] [INFO] Worker exiting (pid: 41)
[2022-05-03 22:08:45 +0800] [42] [INFO] Booting worker with pid: 42
[2022-05-03 22:08:45 +0800] [42] [ERROR] Exception in worker process
Traceback (most recent call last):
  File "/usr/local/lib/python3.7/site-packages/gunicorn/arbiter.py", line 589, in spawn_worker
    worker.init_process()
  File "/usr/local/lib/python3.7/site-packages/gunicorn/workers/ggevent.py", line 146, in init_process
    super().init_process()
  File "/usr/local/lib/python3.7/site-packages/gunicorn/workers/base.py", line 134, in init_process
    self.load_wsgi()
  File "/usr/local/lib/python3.7/site-packages/gunicorn/workers/base.py", line 146, in load_wsgi
    self.wsgi = self.app.wsgi()
  File "/usr/local/lib/python3.7/site-packages/gunicorn/app/base.py", line 67, in wsgi
    self.callable = self.load()
  File "/usr/local/lib/python3.7/site-packages/gunicorn/app/wsgiapp.py", line 58, in load
    return self.load_wsgiapp()
  File "/usr/local/lib/python3.7/site-packages/gunicorn/app/wsgiapp.py", line 48, in load_wsgiapp
    return util.import_app(self.app_uri)
  File "/usr/local/lib/python3.7/site-packages/gunicorn/util.py", line 359, in import_app
    mod = importlib.import_module(module)
  File "/usr/local/lib/python3.7/importlib/__init__.py", line 127, in import_module
    return _bootstrap._gcd_import(name[level:], package, level)
  File "<frozen importlib._bootstrap>", line 1006, in _gcd_import
  File "<frozen importlib._bootstrap>", line 983, in _find_and_load
  File "<frozen importlib._bootstrap>", line 965, in _find_and_load_unlocked
ModuleNotFoundError: No module named 'wsgi'
[2022-05-03 22:08:45 +0800] [42] [INFO] Worker exiting (pid: 42)
Traceback (most recent call last):
  File "/usr/local/lib/python3.7/site-packages/gunicorn/arbiter.py", line 202, in run
    self.manage_workers()
  File "/usr/local/lib/python3.7/site-packages/gunicorn/arbiter.py", line 551, in manage_workers
    self.spawn_workers()
  File "/usr/local/lib/python3.7/site-packages/gunicorn/arbiter.py", line 623, in spawn_workers
    time.sleep(0.1 * random.random())
  File "/usr/local/lib/python3.7/site-packages/gunicorn/arbiter.py", line 242, in handle_chld
    self.reap_workers()
  File "/usr/local/lib/python3.7/site-packages/gunicorn/arbiter.py", line 525, in reap_workers
    raise HaltServer(reason, self.WORKER_BOOT_ERROR)
gunicorn.errors.HaltServer: <HaltServer 'Worker failed to boot.' 3>

During handling of the above exception, another exception occurred:

Traceback (most recent call last):
  File "/usr/local/bin/gunicorn", line 8, in <module>
    sys.exit(run())
  File "/usr/local/lib/python3.7/site-packages/gunicorn/app/wsgiapp.py", line 67, in run
    WSGIApplication("%(prog)s [OPTIONS] [APP_MODULE]").run()
  File "/usr/local/lib/python3.7/site-packages/gunicorn/app/base.py", line 231, in run
    super().run()
  File "/usr/local/lib/python3.7/site-packages/gunicorn/app/base.py", line 72, in run
    Arbiter(self).run()
  File "/usr/local/lib/python3.7/site-packages/gunicorn/arbiter.py", line 229, in run
    self.halt(reason=inst.reason, exit_status=inst.exit_status)
  File "/usr/local/lib/python3.7/site-packages/gunicorn/arbiter.py", line 342, in halt
    self.stop()
  File "/usr/local/lib/python3.7/site-packages/gunicorn/arbiter.py", line 393, in stop
    time.sleep(0.1)
  File "/usr/local/lib/python3.7/site-packages/gunicorn/arbiter.py", line 242, in handle_chld
    self.reap_workers()
  File "/usr/local/lib/python3.7/site-packages/gunicorn/arbiter.py", line 525, in reap_workers
    raise HaltServer(reason, self.WORKER_BOOT_ERROR)
gunicorn.errors.HaltServer: <HaltServer 'Worker failed to boot.' 3>
[2022-05-03 22:08:52 +0800] [43] [INFO] Starting gunicorn 20.1.0
[2022-05-03 22:08:52 +0800] [43] [INFO] Listening at: http://0.0.0.0:8000 (43)
[2022-05-03 22:08:52 +0800] [43] [INFO] Using worker: gevent
[2022-05-03 22:08:52 +0800] [46] [INFO] Booting worker with pid: 46
[2022-05-03 22:08:52 +0800] [47] [INFO] Booting worker with pid: 47
[2022-05-03 22:08:52 +0800] [46] [ERROR] Exception in worker process
Traceback (most recent call last):
  File "/usr/local/lib/python3.7/site-packages/gunicorn/arbiter.py", line 589, in spawn_worker
    worker.init_process()
  File "/usr/local/lib/python3.7/site-packages/gunicorn/workers/ggevent.py", line 146, in init_process
    super().init_process()
  File "/usr/local/lib/python3.7/site-packages/gunicorn/workers/base.py", line 134, in init_process
    self.load_wsgi()
  File "/usr/local/lib/python3.7/site-packages/gunicorn/workers/base.py", line 146, in load_wsgi
    self.wsgi = self.app.wsgi()
  File "/usr/local/lib/python3.7/site-packages/gunicorn/app/base.py", line 67, in wsgi
    self.callable = self.load()
  File "/usr/local/lib/python3.7/site-packages/gunicorn/app/wsgiapp.py", line 58, in load
    return self.load_wsgiapp()
  File "/usr/local/lib/python3.7/site-packages/gunicorn/app/wsgiapp.py", line 48, in load_wsgiapp
    return util.import_app(self.app_uri)
  File "/usr/local/lib/python3.7/site-packages/gunicorn/util.py", line 359, in import_app
    mod = importlib.import_module(module)
  File "/usr/local/lib/python3.7/importlib/__init__.py", line 127, in import_module
    return _bootstrap._gcd_import(name[level:], package, level)
  File "<frozen importlib._bootstrap>", line 1006, in _gcd_import
  File "<frozen importlib._bootstrap>", line 983, in _find_and_load
  File "<frozen importlib._bootstrap>", line 965, in _find_and_load_unlocked
ModuleNotFoundError: No module named 'wsgi'
[2022-05-03 22:08:52 +0800] [46] [INFO] Worker exiting (pid: 46)
[2022-05-03 22:08:53 +0800] [47] [ERROR] Exception in worker process
Traceback (most recent call last):
  File "/usr/local/lib/python3.7/site-packages/gunicorn/arbiter.py", line 589, in spawn_worker
    worker.init_process()
  File "/usr/local/lib/python3.7/site-packages/gunicorn/workers/ggevent.py", line 146, in init_process
    super().init_process()
  File "/usr/local/lib/python3.7/site-packages/gunicorn/workers/base.py", line 134, in init_process
    self.load_wsgi()
  File "/usr/local/lib/python3.7/site-packages/gunicorn/workers/base.py", line 146, in load_wsgi
    self.wsgi = self.app.wsgi()
  File "/usr/local/lib/python3.7/site-packages/gunicorn/app/base.py", line 67, in wsgi
    self.callable = self.load()
  File "/usr/local/lib/python3.7/site-packages/gunicorn/app/wsgiapp.py", line 58, in load
    return self.load_wsgiapp()
  File "/usr/local/lib/python3.7/site-packages/gunicorn/app/wsgiapp.py", line 48, in load_wsgiapp
    return util.import_app(self.app_uri)
  File "/usr/local/lib/python3.7/site-packages/gunicorn/util.py", line 359, in import_app
    mod = importlib.import_module(module)
  File "/usr/local/lib/python3.7/importlib/__init__.py", line 127, in import_module
    return _bootstrap._gcd_import(name[level:], package, level)
  File "<frozen importlib._bootstrap>", line 1006, in _gcd_import
  File "<frozen importlib._bootstrap>", line 983, in _find_and_load
  File "<frozen importlib._bootstrap>", line 965, in _find_and_load_unlocked
ModuleNotFoundError: No module named 'wsgi'
[2022-05-03 22:08:53 +0800] [47] [INFO] Worker exiting (pid: 47)
Traceback (most recent call last):
  File "/usr/local/lib/python3.7/site-packages/gunicorn/arbiter.py", line 202, in run
    self.manage_workers()
  File "/usr/local/lib/python3.7/site-packages/gunicorn/arbiter.py", line 551, in manage_workers
    self.spawn_workers()
  File "/usr/local/lib/python3.7/site-packages/gunicorn/arbiter.py", line 623, in spawn_workers
    time.sleep(0.1 * random.random())
  File "/usr/local/lib/python3.7/site-packages/gunicorn/arbiter.py", line 242, in handle_chld
    self.reap_workers()
  File "/usr/local/lib/python3.7/site-packages/gunicorn/arbiter.py", line 525, in reap_workers
    raise HaltServer(reason, self.WORKER_BOOT_ERROR)
gunicorn.errors.HaltServer: <HaltServer 'Worker failed to boot.' 3>

During handling of the above exception, another exception occurred:

Traceback (most recent call last):
  File "/usr/local/bin/gunicorn", line 8, in <module>
    sys.exit(run())
  File "/usr/local/lib/python3.7/site-packages/gunicorn/app/wsgiapp.py", line 67, in run
    WSGIApplication("%(prog)s [OPTIONS] [APP_MODULE]").run()
  File "/usr/local/lib/python3.7/site-packages/gunicorn/app/base.py", line 231, in run
    super().run()
  File "/usr/local/lib/python3.7/site-packages/gunicorn/app/base.py", line 72, in run
    Arbiter(self).run()
  File "/usr/local/lib/python3.7/site-packages/gunicorn/arbiter.py", line 229, in run
    self.halt(reason=inst.reason, exit_status=inst.exit_status)
  File "/usr/local/lib/python3.7/site-packages/gunicorn/arbiter.py", line 342, in halt
    self.stop()
  File "/usr/local/lib/python3.7/site-packages/gunicorn/arbiter.py", line 393, in stop
    time.sleep(0.1)
  File "/usr/local/lib/python3.7/site-packages/gunicorn/arbiter.py", line 242, in handle_chld
    self.reap_workers()
  File "/usr/local/lib/python3.7/site-packages/gunicorn/arbiter.py", line 525, in reap_workers
    raise HaltServer(reason, self.WORKER_BOOT_ERROR)
gunicorn.errors.HaltServer: <HaltServer 'Worker failed to boot.' 3>
[2022-05-03 22:09:01 +0800] [48] [INFO] Starting gunicorn 20.1.0
[2022-05-03 22:09:01 +0800] [48] [INFO] Listening at: http://0.0.0.0:8000 (48)
[2022-05-03 22:09:01 +0800] [48] [INFO] Using worker: gevent
[2022-05-03 22:09:01 +0800] [51] [INFO] Booting worker with pid: 51
[2022-05-03 22:09:01 +0800] [51] [ERROR] Exception in worker process
Traceback (most recent call last):
  File "/usr/local/lib/python3.7/site-packages/gunicorn/arbiter.py", line 589, in spawn_worker
    worker.init_process()
  File "/usr/local/lib/python3.7/site-packages/gunicorn/workers/ggevent.py", line 146, in init_process
    super().init_process()
  File "/usr/local/lib/python3.7/site-packages/gunicorn/workers/base.py", line 134, in init_process
    self.load_wsgi()
  File "/usr/local/lib/python3.7/site-packages/gunicorn/workers/base.py", line 146, in load_wsgi
    self.wsgi = self.app.wsgi()
  File "/usr/local/lib/python3.7/site-packages/gunicorn/app/base.py", line 67, in wsgi
    self.callable = self.load()
  File "/usr/local/lib/python3.7/site-packages/gunicorn/app/wsgiapp.py", line 58, in load
    return self.load_wsgiapp()
  File "/usr/local/lib/python3.7/site-packages/gunicorn/app/wsgiapp.py", line 48, in load_wsgiapp
    return util.import_app(self.app_uri)
  File "/usr/local/lib/python3.7/site-packages/gunicorn/util.py", line 359, in import_app
    mod = importlib.import_module(module)
  File "/usr/local/lib/python3.7/importlib/__init__.py", line 127, in import_module
    return _bootstrap._gcd_import(name[level:], package, level)
  File "<frozen importlib._bootstrap>", line 1006, in _gcd_import
  File "<frozen importlib._bootstrap>", line 983, in _find_and_load
  File "<frozen importlib._bootstrap>", line 965, in _find_and_load_unlocked
ModuleNotFoundError: No module named 'wsgi'
[2022-05-03 22:09:01 +0800] [51] [INFO] Worker exiting (pid: 51)
[2022-05-03 22:09:01 +0800] [48] [INFO] Shutting down: Master
[2022-05-03 22:09:01 +0800] [48] [INFO] Reason: Worker failed to boot.
[2022-05-03 22:09:10 +0800] [52] [INFO] Starting gunicorn 20.1.0
[2022-05-03 22:09:10 +0800] [52] [INFO] Listening at: http://0.0.0.0:8000 (52)
[2022-05-03 22:09:10 +0800] [52] [INFO] Using worker: gevent
[2022-05-03 22:09:10 +0800] [55] [INFO] Booting worker with pid: 55
[2022-05-03 22:09:10 +0800] [56] [INFO] Booting worker with pid: 56
[2022-05-03 22:09:10 +0800] [55] [ERROR] Exception in worker process
Traceback (most recent call last):
  File "/usr/local/lib/python3.7/site-packages/gunicorn/arbiter.py", line 589, in spawn_worker
    worker.init_process()
  File "/usr/local/lib/python3.7/site-packages/gunicorn/workers/ggevent.py", line 146, in init_process
    super().init_process()
  File "/usr/local/lib/python3.7/site-packages/gunicorn/workers/base.py", line 134, in init_process
    self.load_wsgi()
  File "/usr/local/lib/python3.7/site-packages/gunicorn/workers/base.py", line 146, in load_wsgi
    self.wsgi = self.app.wsgi()
  File "/usr/local/lib/python3.7/site-packages/gunicorn/app/base.py", line 67, in wsgi
    self.callable = self.load()
  File "/usr/local/lib/python3.7/site-packages/gunicorn/app/wsgiapp.py", line 58, in load
    return self.load_wsgiapp()
  File "/usr/local/lib/python3.7/site-packages/gunicorn/app/wsgiapp.py", line 48, in load_wsgiapp
    return util.import_app(self.app_uri)
  File "/usr/local/lib/python3.7/site-packages/gunicorn/util.py", line 359, in import_app
    mod = importlib.import_module(module)
  File "/usr/local/lib/python3.7/importlib/__init__.py", line 127, in import_module
    return _bootstrap._gcd_import(name[level:], package, level)
  File "<frozen importlib._bootstrap>", line 1006, in _gcd_import
  File "<frozen importlib._bootstrap>", line 983, in _find_and_load
  File "<frozen importlib._bootstrap>", line 965, in _find_and_load_unlocked
ModuleNotFoundError: No module named 'wsgi'
[2022-05-03 22:09:10 +0800] [55] [INFO] Worker exiting (pid: 55)
[2022-05-03 22:09:10 +0800] [56] [ERROR] Exception in worker process
Traceback (most recent call last):
  File "/usr/local/lib/python3.7/site-packages/gunicorn/arbiter.py", line 589, in spawn_worker
    worker.init_process()
  File "/usr/local/lib/python3.7/site-packages/gunicorn/workers/ggevent.py", line 146, in init_process
    super().init_process()
  File "/usr/local/lib/python3.7/site-packages/gunicorn/workers/base.py", line 134, in init_process
    self.load_wsgi()
  File "/usr/local/lib/python3.7/site-packages/gunicorn/workers/base.py", line 146, in load_wsgi
    self.wsgi = self.app.wsgi()
  File "/usr/local/lib/python3.7/site-packages/gunicorn/app/base.py", line 67, in wsgi
    self.callable = self.load()
  File "/usr/local/lib/python3.7/site-packages/gunicorn/app/wsgiapp.py", line 58, in load
    return self.load_wsgiapp()
  File "/usr/local/lib/python3.7/site-packages/gunicorn/app/wsgiapp.py", line 48, in load_wsgiapp
    return util.import_app(self.app_uri)
  File "/usr/local/lib/python3.7/site-packages/gunicorn/util.py", line 359, in import_app
    mod = importlib.import_module(module)
  File "/usr/local/lib/python3.7/importlib/__init__.py", line 127, in import_module
    return _bootstrap._gcd_import(name[level:], package, level)
  File "<frozen importlib._bootstrap>", line 1006, in _gcd_import
  File "<frozen importlib._bootstrap>", line 983, in _find_and_load
  File "<frozen importlib._bootstrap>", line 965, in _find_and_load_unlocked
ModuleNotFoundError: No module named 'wsgi'
[2022-05-03 22:09:10 +0800] [56] [INFO] Worker exiting (pid: 56)
[2022-05-03 22:09:10 +0800] [52] [WARNING] Worker with pid 56 was terminated due to signal 15
[2022-05-03 22:09:10 +0800] [52] [INFO] Shutting down: Master
[2022-05-03 22:09:10 +0800] [52] [INFO] Reason: Worker failed to boot.
[2022-05-03 22:09:20 +0800] [57] [INFO] Starting gunicorn 20.1.0
[2022-05-03 22:09:20 +0800] [57] [INFO] Listening at: http://0.0.0.0:8000 (57)
[2022-05-03 22:09:20 +0800] [57] [INFO] Using worker: gevent
[2022-05-03 22:09:20 +0800] [60] [INFO] Booting worker with pid: 60
[2022-05-03 22:09:20 +0800] [61] [INFO] Booting worker with pid: 61
[2022-05-03 22:09:20 +0800] [60] [ERROR] Exception in worker process
Traceback (most recent call last):
  File "/usr/local/lib/python3.7/site-packages/gunicorn/arbiter.py", line 589, in spawn_worker
    worker.init_process()
  File "/usr/local/lib/python3.7/site-packages/gunicorn/workers/ggevent.py", line 146, in init_process
    super().init_process()
  File "/usr/local/lib/python3.7/site-packages/gunicorn/workers/base.py", line 134, in init_process
    self.load_wsgi()
  File "/usr/local/lib/python3.7/site-packages/gunicorn/workers/base.py", line 146, in load_wsgi
    self.wsgi = self.app.wsgi()
  File "/usr/local/lib/python3.7/site-packages/gunicorn/app/base.py", line 67, in wsgi
    self.callable = self.load()
  File "/usr/local/lib/python3.7/site-packages/gunicorn/app/wsgiapp.py", line 58, in load
    return self.load_wsgiapp()
  File "/usr/local/lib/python3.7/site-packages/gunicorn/app/wsgiapp.py", line 48, in load_wsgiapp
    return util.import_app(self.app_uri)
  File "/usr/local/lib/python3.7/site-packages/gunicorn/util.py", line 359, in import_app
    mod = importlib.import_module(module)
  File "/usr/local/lib/python3.7/importlib/__init__.py", line 127, in import_module
    return _bootstrap._gcd_import(name[level:], package, level)
  File "<frozen importlib._bootstrap>", line 1006, in _gcd_import
  File "<frozen importlib._bootstrap>", line 983, in _find_and_load
  File "<frozen importlib._bootstrap>", line 965, in _find_and_load_unlocked
ModuleNotFoundError: No module named 'wsgi'
[2022-05-03 22:09:20 +0800] [60] [INFO] Worker exiting (pid: 60)
[2022-05-03 22:09:20 +0800] [61] [ERROR] Exception in worker process
Traceback (most recent call last):
  File "/usr/local/lib/python3.7/site-packages/gunicorn/arbiter.py", line 589, in spawn_worker
    worker.init_process()
  File "/usr/local/lib/python3.7/site-packages/gunicorn/workers/ggevent.py", line 146, in init_process
    super().init_process()
  File "/usr/local/lib/python3.7/site-packages/gunicorn/workers/base.py", line 134, in init_process
    self.load_wsgi()
  File "/usr/local/lib/python3.7/site-packages/gunicorn/workers/base.py", line 146, in load_wsgi
    self.wsgi = self.app.wsgi()
  File "/usr/local/lib/python3.7/site-packages/gunicorn/app/base.py", line 67, in wsgi
    self.callable = self.load()
  File "/usr/local/lib/python3.7/site-packages/gunicorn/app/wsgiapp.py", line 58, in load
    return self.load_wsgiapp()
  File "/usr/local/lib/python3.7/site-packages/gunicorn/app/wsgiapp.py", line 48, in load_wsgiapp
    return util.import_app(self.app_uri)
  File "/usr/local/lib/python3.7/site-packages/gunicorn/util.py", line 359, in import_app
    mod = importlib.import_module(module)
  File "/usr/local/lib/python3.7/importlib/__init__.py", line 127, in import_module
    return _bootstrap._gcd_import(name[level:], package, level)
  File "<frozen importlib._bootstrap>", line 1006, in _gcd_import
  File "<frozen importlib._bootstrap>", line 983, in _find_and_load
  File "<frozen importlib._bootstrap>", line 965, in _find_and_load_unlocked
ModuleNotFoundError: No module named 'wsgi'
[2022-05-03 22:09:20 +0800] [61] [INFO] Worker exiting (pid: 61)
Traceback (most recent call last):
  File "/usr/local/lib/python3.7/site-packages/gunicorn/arbiter.py", line 209, in run
    self.sleep()
  File "/usr/local/lib/python3.7/site-packages/gunicorn/arbiter.py", line 357, in sleep
    ready = select.select([self.PIPE[0]], [], [], 1.0)
  File "/usr/local/lib/python3.7/site-packages/gunicorn/arbiter.py", line 242, in handle_chld
    self.reap_workers()
  File "/usr/local/lib/python3.7/site-packages/gunicorn/arbiter.py", line 525, in reap_workers
    raise HaltServer(reason, self.WORKER_BOOT_ERROR)
gunicorn.errors.HaltServer: <HaltServer 'Worker failed to boot.' 3>

During handling of the above exception, another exception occurred:

Traceback (most recent call last):
  File "/usr/local/bin/gunicorn", line 8, in <module>
    sys.exit(run())
  File "/usr/local/lib/python3.7/site-packages/gunicorn/app/wsgiapp.py", line 67, in run
    WSGIApplication("%(prog)s [OPTIONS] [APP_MODULE]").run()
  File "/usr/local/lib/python3.7/site-packages/gunicorn/app/base.py", line 231, in run
    super().run()
  File "/usr/local/lib/python3.7/site-packages/gunicorn/app/base.py", line 72, in run
    Arbiter(self).run()
  File "/usr/local/lib/python3.7/site-packages/gunicorn/arbiter.py", line 229, in run
    self.halt(reason=inst.reason, exit_status=inst.exit_status)
  File "/usr/local/lib/python3.7/site-packages/gunicorn/arbiter.py", line 342, in halt
    self.stop()
  File "/usr/local/lib/python3.7/site-packages/gunicorn/arbiter.py", line 393, in stop
    time.sleep(0.1)
  File "/usr/local/lib/python3.7/site-packages/gunicorn/arbiter.py", line 242, in handle_chld
    self.reap_workers()
  File "/usr/local/lib/python3.7/site-packages/gunicorn/arbiter.py", line 525, in reap_workers
    raise HaltServer(reason, self.WORKER_BOOT_ERROR)
gunicorn.errors.HaltServer: <HaltServer 'Worker failed to boot.' 3>
[2022-05-03 22:09:32 +0800] [72] [INFO] Starting gunicorn 20.1.0
[2022-05-03 22:09:32 +0800] [72] [INFO] Listening at: http://0.0.0.0:8000 (72)
[2022-05-03 22:09:32 +0800] [72] [INFO] Using worker: gevent
[2022-05-03 22:09:32 +0800] [75] [INFO] Booting worker with pid: 75
[2022-05-03 22:09:32 +0800] [75] [ERROR] Exception in worker process
Traceback (most recent call last):
  File "/usr/local/lib/python3.7/site-packages/gunicorn/arbiter.py", line 589, in spawn_worker
    worker.init_process()
  File "/usr/local/lib/python3.7/site-packages/gunicorn/workers/ggevent.py", line 146, in init_process
    super().init_process()
  File "/usr/local/lib/python3.7/site-packages/gunicorn/workers/base.py", line 134, in init_process
    self.load_wsgi()
  File "/usr/local/lib/python3.7/site-packages/gunicorn/workers/base.py", line 146, in load_wsgi
    self.wsgi = self.app.wsgi()
  File "/usr/local/lib/python3.7/site-packages/gunicorn/app/base.py", line 67, in wsgi
    self.callable = self.load()
  File "/usr/local/lib/python3.7/site-packages/gunicorn/app/wsgiapp.py", line 58, in load
    return self.load_wsgiapp()
  File "/usr/local/lib/python3.7/site-packages/gunicorn/app/wsgiapp.py", line 48, in load_wsgiapp
    return util.import_app(self.app_uri)
  File "/usr/local/lib/python3.7/site-packages/gunicorn/util.py", line 359, in import_app
    mod = importlib.import_module(module)
  File "/usr/local/lib/python3.7/importlib/__init__.py", line 127, in import_module
    return _bootstrap._gcd_import(name[level:], package, level)
  File "<frozen importlib._bootstrap>", line 1006, in _gcd_import
  File "<frozen importlib._bootstrap>", line 983, in _find_and_load
  File "<frozen importlib._bootstrap>", line 965, in _find_and_load_unlocked
ModuleNotFoundError: No module named 'wsgi'
[2022-05-03 22:09:32 +0800] [75] [INFO] Worker exiting (pid: 75)
[2022-05-03 22:09:32 +0800] [76] [INFO] Booting worker with pid: 76
[2022-05-03 22:09:32 +0800] [76] [ERROR] Exception in worker process
Traceback (most recent call last):
  File "/usr/local/lib/python3.7/site-packages/gunicorn/arbiter.py", line 589, in spawn_worker
    worker.init_process()
  File "/usr/local/lib/python3.7/site-packages/gunicorn/workers/ggevent.py", line 146, in init_process
    super().init_process()
  File "/usr/local/lib/python3.7/site-packages/gunicorn/workers/base.py", line 134, in init_process
    self.load_wsgi()
  File "/usr/local/lib/python3.7/site-packages/gunicorn/workers/base.py", line 146, in load_wsgi
    self.wsgi = self.app.wsgi()
  File "/usr/local/lib/python3.7/site-packages/gunicorn/app/base.py", line 67, in wsgi
    self.callable = self.load()
  File "/usr/local/lib/python3.7/site-packages/gunicorn/app/wsgiapp.py", line 58, in load
    return self.load_wsgiapp()
  File "/usr/local/lib/python3.7/site-packages/gunicorn/app/wsgiapp.py", line 48, in load_wsgiapp
    return util.import_app(self.app_uri)
  File "/usr/local/lib/python3.7/site-packages/gunicorn/util.py", line 359, in import_app
    mod = importlib.import_module(module)
  File "/usr/local/lib/python3.7/importlib/__init__.py", line 127, in import_module
    return _bootstrap._gcd_import(name[level:], package, level)
  File "<frozen importlib._bootstrap>", line 1006, in _gcd_import
  File "<frozen importlib._bootstrap>", line 983, in _find_and_load
  File "<frozen importlib._bootstrap>", line 965, in _find_and_load_unlocked
ModuleNotFoundError: No module named 'wsgi'
[2022-05-03 22:09:32 +0800] [76] [INFO] Worker exiting (pid: 76)
Traceback (most recent call last):
  File "/usr/local/lib/python3.7/site-packages/gunicorn/arbiter.py", line 202, in run
    self.manage_workers()
  File "/usr/local/lib/python3.7/site-packages/gunicorn/arbiter.py", line 551, in manage_workers
    self.spawn_workers()
  File "/usr/local/lib/python3.7/site-packages/gunicorn/arbiter.py", line 623, in spawn_workers
    time.sleep(0.1 * random.random())
  File "/usr/local/lib/python3.7/site-packages/gunicorn/arbiter.py", line 242, in handle_chld
    self.reap_workers()
  File "/usr/local/lib/python3.7/site-packages/gunicorn/arbiter.py", line 525, in reap_workers
    raise HaltServer(reason, self.WORKER_BOOT_ERROR)
gunicorn.errors.HaltServer: <HaltServer 'Worker failed to boot.' 3>

During handling of the above exception, another exception occurred:

Traceback (most recent call last):
  File "/usr/local/bin/gunicorn", line 8, in <module>
    sys.exit(run())
  File "/usr/local/lib/python3.7/site-packages/gunicorn/app/wsgiapp.py", line 67, in run
    WSGIApplication("%(prog)s [OPTIONS] [APP_MODULE]").run()
  File "/usr/local/lib/python3.7/site-packages/gunicorn/app/base.py", line 231, in run
    super().run()
  File "/usr/local/lib/python3.7/site-packages/gunicorn/app/base.py", line 72, in run
    Arbiter(self).run()
  File "/usr/local/lib/python3.7/site-packages/gunicorn/arbiter.py", line 229, in run
    self.halt(reason=inst.reason, exit_status=inst.exit_status)
  File "/usr/local/lib/python3.7/site-packages/gunicorn/arbiter.py", line 342, in halt
    self.stop()
  File "/usr/local/lib/python3.7/site-packages/gunicorn/arbiter.py", line 393, in stop
    time.sleep(0.1)
  File "/usr/local/lib/python3.7/site-packages/gunicorn/arbiter.py", line 242, in handle_chld
    self.reap_workers()
  File "/usr/local/lib/python3.7/site-packages/gunicorn/arbiter.py", line 525, in reap_workers
    raise HaltServer(reason, self.WORKER_BOOT_ERROR)
gunicorn.errors.HaltServer: <HaltServer 'Worker failed to boot.' 3>
[2022-05-03 22:09:44 +0800] [77] [INFO] Starting gunicorn 20.1.0
[2022-05-03 22:09:44 +0800] [77] [INFO] Listening at: http://0.0.0.0:8000 (77)
[2022-05-03 22:09:44 +0800] [77] [INFO] Using worker: gevent
[2022-05-03 22:09:44 +0800] [80] [INFO] Booting worker with pid: 80
[2022-05-03 22:09:44 +0800] [80] [ERROR] Exception in worker process
Traceback (most recent call last):
  File "/usr/local/lib/python3.7/site-packages/gunicorn/arbiter.py", line 589, in spawn_worker
    worker.init_process()
  File "/usr/local/lib/python3.7/site-packages/gunicorn/workers/ggevent.py", line 146, in init_process
    super().init_process()
  File "/usr/local/lib/python3.7/site-packages/gunicorn/workers/base.py", line 134, in init_process
    self.load_wsgi()
  File "/usr/local/lib/python3.7/site-packages/gunicorn/workers/base.py", line 146, in load_wsgi
    self.wsgi = self.app.wsgi()
  File "/usr/local/lib/python3.7/site-packages/gunicorn/app/base.py", line 67, in wsgi
    self.callable = self.load()
  File "/usr/local/lib/python3.7/site-packages/gunicorn/app/wsgiapp.py", line 58, in load
    return self.load_wsgiapp()
  File "/usr/local/lib/python3.7/site-packages/gunicorn/app/wsgiapp.py", line 48, in load_wsgiapp
    return util.import_app(self.app_uri)
  File "/usr/local/lib/python3.7/site-packages/gunicorn/util.py", line 359, in import_app
    mod = importlib.import_module(module)
  File "/usr/local/lib/python3.7/importlib/__init__.py", line 127, in import_module
    return _bootstrap._gcd_import(name[level:], package, level)
  File "<frozen importlib._bootstrap>", line 1006, in _gcd_import
  File "<frozen importlib._bootstrap>", line 983, in _find_and_load
  File "<frozen importlib._bootstrap>", line 965, in _find_and_load_unlocked
ModuleNotFoundError: No module named 'wsgi'
[2022-05-03 22:09:44 +0800] [80] [INFO] Worker exiting (pid: 80)
[2022-05-03 22:09:44 +0800] [77] [INFO] Shutting down: Master
[2022-05-03 22:09:44 +0800] [77] [INFO] Reason: Worker failed to boot.
[2022-05-03 22:09:57 +0800] [81] [INFO] Starting gunicorn 20.1.0
[2022-05-03 22:09:57 +0800] [81] [INFO] Listening at: http://0.0.0.0:8000 (81)
[2022-05-03 22:09:57 +0800] [81] [INFO] Using worker: gevent
[2022-05-03 22:09:57 +0800] [84] [INFO] Booting worker with pid: 84
[2022-05-03 22:09:57 +0800] [85] [INFO] Booting worker with pid: 85
[2022-05-03 22:09:57 +0800] [84] [ERROR] Exception in worker process
Traceback (most recent call last):
  File "/usr/local/lib/python3.7/site-packages/gunicorn/arbiter.py", line 589, in spawn_worker
    worker.init_process()
  File "/usr/local/lib/python3.7/site-packages/gunicorn/workers/ggevent.py", line 146, in init_process
    super().init_process()
  File "/usr/local/lib/python3.7/site-packages/gunicorn/workers/base.py", line 134, in init_process
    self.load_wsgi()
  File "/usr/local/lib/python3.7/site-packages/gunicorn/workers/base.py", line 146, in load_wsgi
    self.wsgi = self.app.wsgi()
  File "/usr/local/lib/python3.7/site-packages/gunicorn/app/base.py", line 67, in wsgi
    self.callable = self.load()
  File "/usr/local/lib/python3.7/site-packages/gunicorn/app/wsgiapp.py", line 58, in load
    return self.load_wsgiapp()
  File "/usr/local/lib/python3.7/site-packages/gunicorn/app/wsgiapp.py", line 48, in load_wsgiapp
    return util.import_app(self.app_uri)
  File "/usr/local/lib/python3.7/site-packages/gunicorn/util.py", line 359, in import_app
    mod = importlib.import_module(module)
  File "/usr/local/lib/python3.7/importlib/__init__.py", line 127, in import_module
    return _bootstrap._gcd_import(name[level:], package, level)
  File "<frozen importlib._bootstrap>", line 1006, in _gcd_import
  File "<frozen importlib._bootstrap>", line 983, in _find_and_load
  File "<frozen importlib._bootstrap>", line 965, in _find_and_load_unlocked
ModuleNotFoundError: No module named 'wsgi'
[2022-05-03 22:09:57 +0800] [84] [INFO] Worker exiting (pid: 84)
[2022-05-03 22:09:57 +0800] [85] [ERROR] Exception in worker process
Traceback (most recent call last):
  File "/usr/local/lib/python3.7/site-packages/gunicorn/arbiter.py", line 589, in spawn_worker
    worker.init_process()
  File "/usr/local/lib/python3.7/site-packages/gunicorn/workers/ggevent.py", line 146, in init_process
    super().init_process()
  File "/usr/local/lib/python3.7/site-packages/gunicorn/workers/base.py", line 134, in init_process
    self.load_wsgi()
  File "/usr/local/lib/python3.7/site-packages/gunicorn/workers/base.py", line 146, in load_wsgi
    self.wsgi = self.app.wsgi()
  File "/usr/local/lib/python3.7/site-packages/gunicorn/app/base.py", line 67, in wsgi
    self.callable = self.load()
  File "/usr/local/lib/python3.7/site-packages/gunicorn/app/wsgiapp.py", line 58, in load
    return self.load_wsgiapp()
  File "/usr/local/lib/python3.7/site-packages/gunicorn/app/wsgiapp.py", line 48, in load_wsgiapp
    return util.import_app(self.app_uri)
  File "/usr/local/lib/python3.7/site-packages/gunicorn/util.py", line 359, in import_app
    mod = importlib.import_module(module)
  File "/usr/local/lib/python3.7/importlib/__init__.py", line 127, in import_module
    return _bootstrap._gcd_import(name[level:], package, level)
  File "<frozen importlib._bootstrap>", line 1006, in _gcd_import
  File "<frozen importlib._bootstrap>", line 983, in _find_and_load
  File "<frozen importlib._bootstrap>", line 965, in _find_and_load_unlocked
ModuleNotFoundError: No module named 'wsgi'
[2022-05-03 22:09:57 +0800] [85] [INFO] Worker exiting (pid: 85)
Traceback (most recent call last):
  File "/usr/local/lib/python3.7/site-packages/gunicorn/arbiter.py", line 209, in run
    self.sleep()
  File "/usr/local/lib/python3.7/site-packages/gunicorn/arbiter.py", line 357, in sleep
    ready = select.select([self.PIPE[0]], [], [], 1.0)
  File "/usr/local/lib/python3.7/site-packages/gunicorn/arbiter.py", line 242, in handle_chld
    self.reap_workers()
  File "/usr/local/lib/python3.7/site-packages/gunicorn/arbiter.py", line 525, in reap_workers
    raise HaltServer(reason, self.WORKER_BOOT_ERROR)
gunicorn.errors.HaltServer: <HaltServer 'Worker failed to boot.' 3>

During handling of the above exception, another exception occurred:

Traceback (most recent call last):
  File "/usr/local/lib/python3.7/site-packages/gunicorn/arbiter.py", line 642, in kill_worker
    os.kill(pid, sig)
ProcessLookupError: [Errno 3] No such process

During handling of the above exception, another exception occurred:

Traceback (most recent call last):
  File "/usr/local/bin/gunicorn", line 8, in <module>
    sys.exit(run())
  File "/usr/local/lib/python3.7/site-packages/gunicorn/app/wsgiapp.py", line 67, in run
    WSGIApplication("%(prog)s [OPTIONS] [APP_MODULE]").run()
  File "/usr/local/lib/python3.7/site-packages/gunicorn/app/base.py", line 231, in run
    super().run()
  File "/usr/local/lib/python3.7/site-packages/gunicorn/app/base.py", line 72, in run
    Arbiter(self).run()
  File "/usr/local/lib/python3.7/site-packages/gunicorn/arbiter.py", line 229, in run
    self.halt(reason=inst.reason, exit_status=inst.exit_status)
  File "/usr/local/lib/python3.7/site-packages/gunicorn/arbiter.py", line 342, in halt
    self.stop()
  File "/usr/local/lib/python3.7/site-packages/gunicorn/arbiter.py", line 390, in stop
    self.kill_workers(sig)
  File "/usr/local/lib/python3.7/site-packages/gunicorn/arbiter.py", line 632, in kill_workers
    self.kill_worker(pid, sig)
  File "/usr/local/lib/python3.7/site-packages/gunicorn/arbiter.py", line 644, in kill_worker
    if e.errno == errno.ESRCH:
  File "/usr/local/lib/python3.7/site-packages/gunicorn/arbiter.py", line 242, in handle_chld
    self.reap_workers()
  File "/usr/local/lib/python3.7/site-packages/gunicorn/arbiter.py", line 525, in reap_workers
    raise HaltServer(reason, self.WORKER_BOOT_ERROR)
gunicorn.errors.HaltServer: <HaltServer 'Worker failed to boot.' 3>
[2022-05-03 22:10:12 +0800] [88] [INFO] Starting gunicorn 20.1.0
[2022-05-03 22:10:12 +0800] [88] [INFO] Listening at: http://0.0.0.0:8000 (88)
[2022-05-03 22:10:12 +0800] [88] [INFO] Using worker: gevent
[2022-05-03 22:10:12 +0800] [91] [INFO] Booting worker with pid: 91
[2022-05-03 22:10:12 +0800] [91] [ERROR] Exception in worker process
Traceback (most recent call last):
  File "/usr/local/lib/python3.7/site-packages/gunicorn/arbiter.py", line 589, in spawn_worker
    worker.init_process()
  File "/usr/local/lib/python3.7/site-packages/gunicorn/workers/ggevent.py", line 146, in init_process
    super().init_process()
  File "/usr/local/lib/python3.7/site-packages/gunicorn/workers/base.py", line 134, in init_process
    self.load_wsgi()
  File "/usr/local/lib/python3.7/site-packages/gunicorn/workers/base.py", line 146, in load_wsgi
    self.wsgi = self.app.wsgi()
  File "/usr/local/lib/python3.7/site-packages/gunicorn/app/base.py", line 67, in wsgi
    self.callable = self.load()
  File "/usr/local/lib/python3.7/site-packages/gunicorn/app/wsgiapp.py", line 58, in load
    return self.load_wsgiapp()
  File "/usr/local/lib/python3.7/site-packages/gunicorn/app/wsgiapp.py", line 48, in load_wsgiapp
    return util.import_app(self.app_uri)
  File "/usr/local/lib/python3.7/site-packages/gunicorn/util.py", line 359, in import_app
    mod = importlib.import_module(module)
  File "/usr/local/lib/python3.7/importlib/__init__.py", line 127, in import_module
    return _bootstrap._gcd_import(name[level:], package, level)
  File "<frozen importlib._bootstrap>", line 1006, in _gcd_import
  File "<frozen importlib._bootstrap>", line 983, in _find_and_load
  File "<frozen importlib._bootstrap>", line 965, in _find_and_load_unlocked
ModuleNotFoundError: No module named 'wsgi'
[2022-05-03 22:10:12 +0800] [91] [INFO] Worker exiting (pid: 91)
[2022-05-03 22:10:12 +0800] [92] [INFO] Booting worker with pid: 92
[2022-05-03 22:10:12 +0800] [92] [ERROR] Exception in worker process
Traceback (most recent call last):
  File "/usr/local/lib/python3.7/site-packages/gunicorn/arbiter.py", line 589, in spawn_worker
    worker.init_process()
  File "/usr/local/lib/python3.7/site-packages/gunicorn/workers/ggevent.py", line 146, in init_process
    super().init_process()
  File "/usr/local/lib/python3.7/site-packages/gunicorn/workers/base.py", line 134, in init_process
    self.load_wsgi()
  File "/usr/local/lib/python3.7/site-packages/gunicorn/workers/base.py", line 146, in load_wsgi
    self.wsgi = self.app.wsgi()
  File "/usr/local/lib/python3.7/site-packages/gunicorn/app/base.py", line 67, in wsgi
    self.callable = self.load()
  File "/usr/local/lib/python3.7/site-packages/gunicorn/app/wsgiapp.py", line 58, in load
    return self.load_wsgiapp()
  File "/usr/local/lib/python3.7/site-packages/gunicorn/app/wsgiapp.py", line 48, in load_wsgiapp
    return util.import_app(self.app_uri)
  File "/usr/local/lib/python3.7/site-packages/gunicorn/util.py", line 359, in import_app
    mod = importlib.import_module(module)
  File "/usr/local/lib/python3.7/importlib/__init__.py", line 127, in import_module
    return _bootstrap._gcd_import(name[level:], package, level)
  File "<frozen importlib._bootstrap>", line 1006, in _gcd_import
  File "<frozen importlib._bootstrap>", line 983, in _find_and_load
  File "<frozen importlib._bootstrap>", line 965, in _find_and_load_unlocked
ModuleNotFoundError: No module named 'wsgi'
[2022-05-03 22:10:12 +0800] [92] [INFO] Worker exiting (pid: 92)
Traceback (most recent call last):
  File "/usr/local/lib/python3.7/site-packages/gunicorn/arbiter.py", line 202, in run
    self.manage_workers()
  File "/usr/local/lib/python3.7/site-packages/gunicorn/arbiter.py", line 551, in manage_workers
    self.spawn_workers()
  File "/usr/local/lib/python3.7/site-packages/gunicorn/arbiter.py", line 623, in spawn_workers
    time.sleep(0.1 * random.random())
  File "/usr/local/lib/python3.7/site-packages/gunicorn/arbiter.py", line 242, in handle_chld
    self.reap_workers()
  File "/usr/local/lib/python3.7/site-packages/gunicorn/arbiter.py", line 525, in reap_workers
    raise HaltServer(reason, self.WORKER_BOOT_ERROR)
gunicorn.errors.HaltServer: <HaltServer 'Worker failed to boot.' 3>

During handling of the above exception, another exception occurred:

Traceback (most recent call last):
  File "/usr/local/bin/gunicorn", line 8, in <module>
    sys.exit(run())
  File "/usr/local/lib/python3.7/site-packages/gunicorn/app/wsgiapp.py", line 67, in run
    WSGIApplication("%(prog)s [OPTIONS] [APP_MODULE]").run()
  File "/usr/local/lib/python3.7/site-packages/gunicorn/app/base.py", line 231, in run
    super().run()
  File "/usr/local/lib/python3.7/site-packages/gunicorn/app/base.py", line 72, in run
    Arbiter(self).run()
  File "/usr/local/lib/python3.7/site-packages/gunicorn/arbiter.py", line 229, in run
    self.halt(reason=inst.reason, exit_status=inst.exit_status)
  File "/usr/local/lib/python3.7/site-packages/gunicorn/arbiter.py", line 342, in halt
    self.stop()
  File "/usr/local/lib/python3.7/site-packages/gunicorn/arbiter.py", line 393, in stop
    time.sleep(0.1)
  File "/usr/local/lib/python3.7/site-packages/gunicorn/arbiter.py", line 242, in handle_chld
    self.reap_workers()
  File "/usr/local/lib/python3.7/site-packages/gunicorn/arbiter.py", line 525, in reap_workers
    raise HaltServer(reason, self.WORKER_BOOT_ERROR)
gunicorn.errors.HaltServer: <HaltServer 'Worker failed to boot.' 3>
[2022-05-03 22:10:27 +0800] [94] [INFO] Starting gunicorn 20.1.0
[2022-05-03 22:10:27 +0800] [94] [INFO] Listening at: http://0.0.0.0:8000 (94)
[2022-05-03 22:10:27 +0800] [94] [INFO] Using worker: gevent
[2022-05-03 22:10:27 +0800] [97] [INFO] Booting worker with pid: 97
[2022-05-03 22:10:27 +0800] [98] [INFO] Booting worker with pid: 98
[2022-05-03 22:10:27 +0800] [97] [ERROR] Exception in worker process
Traceback (most recent call last):
  File "/usr/local/lib/python3.7/site-packages/gunicorn/arbiter.py", line 589, in spawn_worker
    worker.init_process()
  File "/usr/local/lib/python3.7/site-packages/gunicorn/workers/ggevent.py", line 146, in init_process
    super().init_process()
  File "/usr/local/lib/python3.7/site-packages/gunicorn/workers/base.py", line 134, in init_process
    self.load_wsgi()
  File "/usr/local/lib/python3.7/site-packages/gunicorn/workers/base.py", line 146, in load_wsgi
    self.wsgi = self.app.wsgi()
  File "/usr/local/lib/python3.7/site-packages/gunicorn/app/base.py", line 67, in wsgi
    self.callable = self.load()
  File "/usr/local/lib/python3.7/site-packages/gunicorn/app/wsgiapp.py", line 58, in load
    return self.load_wsgiapp()
  File "/usr/local/lib/python3.7/site-packages/gunicorn/app/wsgiapp.py", line 48, in load_wsgiapp
    return util.import_app(self.app_uri)
  File "/usr/local/lib/python3.7/site-packages/gunicorn/util.py", line 359, in import_app
    mod = importlib.import_module(module)
  File "/usr/local/lib/python3.7/importlib/__init__.py", line 127, in import_module
    return _bootstrap._gcd_import(name[level:], package, level)
  File "<frozen importlib._bootstrap>", line 1006, in _gcd_import
  File "<frozen importlib._bootstrap>", line 983, in _find_and_load
  File "<frozen importlib._bootstrap>", line 965, in _find_and_load_unlocked
ModuleNotFoundError: No module named 'wsgi'
[2022-05-03 22:10:27 +0800] [97] [INFO] Worker exiting (pid: 97)
[2022-05-03 22:10:27 +0800] [98] [ERROR] Exception in worker process
Traceback (most recent call last):
  File "/usr/local/lib/python3.7/site-packages/gunicorn/arbiter.py", line 589, in spawn_worker
    worker.init_process()
  File "/usr/local/lib/python3.7/site-packages/gunicorn/workers/ggevent.py", line 146, in init_process
    super().init_process()
  File "/usr/local/lib/python3.7/site-packages/gunicorn/workers/base.py", line 134, in init_process
    self.load_wsgi()
  File "/usr/local/lib/python3.7/site-packages/gunicorn/workers/base.py", line 146, in load_wsgi
    self.wsgi = self.app.wsgi()
  File "/usr/local/lib/python3.7/site-packages/gunicorn/app/base.py", line 67, in wsgi
    self.callable = self.load()
  File "/usr/local/lib/python3.7/site-packages/gunicorn/app/wsgiapp.py", line 58, in load
    return self.load_wsgiapp()
  File "/usr/local/lib/python3.7/site-packages/gunicorn/app/wsgiapp.py", line 48, in load_wsgiapp
    return util.import_app(self.app_uri)
  File "/usr/local/lib/python3.7/site-packages/gunicorn/util.py", line 359, in import_app
    mod = importlib.import_module(module)
  File "/usr/local/lib/python3.7/importlib/__init__.py", line 127, in import_module
    return _bootstrap._gcd_import(name[level:], package, level)
  File "<frozen importlib._bootstrap>", line 1006, in _gcd_import
  File "<frozen importlib._bootstrap>", line 983, in _find_and_load
  File "<frozen importlib._bootstrap>", line 965, in _find_and_load_unlocked
ModuleNotFoundError: No module named 'wsgi'
[2022-05-03 22:10:27 +0800] [98] [INFO] Worker exiting (pid: 98)
Traceback (most recent call last):
  File "/usr/local/lib/python3.7/site-packages/gunicorn/arbiter.py", line 202, in run
    self.manage_workers()
  File "/usr/local/lib/python3.7/site-packages/gunicorn/arbiter.py", line 551, in manage_workers
    self.spawn_workers()
  File "/usr/local/lib/python3.7/site-packages/gunicorn/arbiter.py", line 623, in spawn_workers
    time.sleep(0.1 * random.random())
  File "/usr/local/lib/python3.7/site-packages/gunicorn/arbiter.py", line 242, in handle_chld
    self.reap_workers()
  File "/usr/local/lib/python3.7/site-packages/gunicorn/arbiter.py", line 525, in reap_workers
    raise HaltServer(reason, self.WORKER_BOOT_ERROR)
gunicorn.errors.HaltServer: <HaltServer 'Worker failed to boot.' 3>

During handling of the above exception, another exception occurred:

Traceback (most recent call last):
  File "/usr/local/bin/gunicorn", line 8, in <module>
    sys.exit(run())
  File "/usr/local/lib/python3.7/site-packages/gunicorn/app/wsgiapp.py", line 67, in run
    WSGIApplication("%(prog)s [OPTIONS] [APP_MODULE]").run()
  File "/usr/local/lib/python3.7/site-packages/gunicorn/app/base.py", line 231, in run
    super().run()
  File "/usr/local/lib/python3.7/site-packages/gunicorn/app/base.py", line 72, in run
    Arbiter(self).run()
  File "/usr/local/lib/python3.7/site-packages/gunicorn/arbiter.py", line 229, in run
    self.halt(reason=inst.reason, exit_status=inst.exit_status)
  File "/usr/local/lib/python3.7/site-packages/gunicorn/arbiter.py", line 342, in halt
    self.stop()
  File "/usr/local/lib/python3.7/site-packages/gunicorn/arbiter.py", line 393, in stop
    time.sleep(0.1)
  File "/usr/local/lib/python3.7/site-packages/gunicorn/arbiter.py", line 242, in handle_chld
    self.reap_workers()
  File "/usr/local/lib/python3.7/site-packages/gunicorn/arbiter.py", line 525, in reap_workers
    raise HaltServer(reason, self.WORKER_BOOT_ERROR)
gunicorn.errors.HaltServer: <HaltServer 'Worker failed to boot.' 3>
[2022-05-03 22:10:43 +0800] [102] [INFO] Starting gunicorn 20.1.0
[2022-05-03 22:10:43 +0800] [102] [INFO] Listening at: http://0.0.0.0:8000 (102)
[2022-05-03 22:10:43 +0800] [102] [INFO] Using worker: gevent
[2022-05-03 22:10:43 +0800] [105] [INFO] Booting worker with pid: 105
[2022-05-03 22:10:43 +0800] [106] [INFO] Booting worker with pid: 106
[2022-05-03 22:10:43 +0800] [105] [ERROR] Exception in worker process
Traceback (most recent call last):
  File "/usr/local/lib/python3.7/site-packages/gunicorn/arbiter.py", line 589, in spawn_worker
    worker.init_process()
  File "/usr/local/lib/python3.7/site-packages/gunicorn/workers/ggevent.py", line 146, in init_process
    super().init_process()
  File "/usr/local/lib/python3.7/site-packages/gunicorn/workers/base.py", line 134, in init_process
    self.load_wsgi()
  File "/usr/local/lib/python3.7/site-packages/gunicorn/workers/base.py", line 146, in load_wsgi
    self.wsgi = self.app.wsgi()
  File "/usr/local/lib/python3.7/site-packages/gunicorn/app/base.py", line 67, in wsgi
    self.callable = self.load()
  File "/usr/local/lib/python3.7/site-packages/gunicorn/app/wsgiapp.py", line 58, in load
    return self.load_wsgiapp()
  File "/usr/local/lib/python3.7/site-packages/gunicorn/app/wsgiapp.py", line 48, in load_wsgiapp
    return util.import_app(self.app_uri)
  File "/usr/local/lib/python3.7/site-packages/gunicorn/util.py", line 359, in import_app
    mod = importlib.import_module(module)
  File "/usr/local/lib/python3.7/importlib/__init__.py", line 127, in import_module
    return _bootstrap._gcd_import(name[level:], package, level)
  File "<frozen importlib._bootstrap>", line 1006, in _gcd_import
  File "<frozen importlib._bootstrap>", line 983, in _find_and_load
  File "<frozen importlib._bootstrap>", line 965, in _find_and_load_unlocked
ModuleNotFoundError: No module named 'wsgi'
[2022-05-03 22:10:43 +0800] [105] [INFO] Worker exiting (pid: 105)
[2022-05-03 22:10:43 +0800] [106] [ERROR] Exception in worker process
Traceback (most recent call last):
  File "/usr/local/lib/python3.7/site-packages/gunicorn/arbiter.py", line 589, in spawn_worker
    worker.init_process()
  File "/usr/local/lib/python3.7/site-packages/gunicorn/workers/ggevent.py", line 146, in init_process
    super().init_process()
  File "/usr/local/lib/python3.7/site-packages/gunicorn/workers/base.py", line 134, in init_process
    self.load_wsgi()
  File "/usr/local/lib/python3.7/site-packages/gunicorn/workers/base.py", line 146, in load_wsgi
    self.wsgi = self.app.wsgi()
  File "/usr/local/lib/python3.7/site-packages/gunicorn/app/base.py", line 67, in wsgi
    self.callable = self.load()
  File "/usr/local/lib/python3.7/site-packages/gunicorn/app/wsgiapp.py", line 58, in load
    return self.load_wsgiapp()
  File "/usr/local/lib/python3.7/site-packages/gunicorn/app/wsgiapp.py", line 48, in load_wsgiapp
    return util.import_app(self.app_uri)
  File "/usr/local/lib/python3.7/site-packages/gunicorn/util.py", line 359, in import_app
    mod = importlib.import_module(module)
  File "/usr/local/lib/python3.7/importlib/__init__.py", line 127, in import_module
    return _bootstrap._gcd_import(name[level:], package, level)
  File "<frozen importlib._bootstrap>", line 1006, in _gcd_import
  File "<frozen importlib._bootstrap>", line 983, in _find_and_load
  File "<frozen importlib._bootstrap>", line 965, in _find_and_load_unlocked
ModuleNotFoundError: No module named 'wsgi'
[2022-05-03 22:10:43 +0800] [106] [INFO] Worker exiting (pid: 106)
[2022-05-03 22:10:43 +0800] [102] [WARNING] Worker with pid 106 was terminated due to signal 15
[2022-05-03 22:10:43 +0800] [102] [INFO] Shutting down: Master
[2022-05-03 22:10:43 +0800] [102] [INFO] Reason: Worker failed to boot.
[2022-05-03 22:11:01 +0800] [108] [INFO] Starting gunicorn 20.1.0
[2022-05-03 22:11:01 +0800] [108] [INFO] Listening at: http://0.0.0.0:8000 (108)
[2022-05-03 22:11:01 +0800] [108] [INFO] Using worker: gevent
[2022-05-03 22:11:01 +0800] [111] [INFO] Booting worker with pid: 111
[2022-05-03 22:11:01 +0800] [111] [ERROR] Exception in worker process
Traceback (most recent call last):
  File "/usr/local/lib/python3.7/site-packages/gunicorn/arbiter.py", line 589, in spawn_worker
    worker.init_process()
  File "/usr/local/lib/python3.7/site-packages/gunicorn/workers/ggevent.py", line 146, in init_process
    super().init_process()
  File "/usr/local/lib/python3.7/site-packages/gunicorn/workers/base.py", line 134, in init_process
    self.load_wsgi()
  File "/usr/local/lib/python3.7/site-packages/gunicorn/workers/base.py", line 146, in load_wsgi
    self.wsgi = self.app.wsgi()
  File "/usr/local/lib/python3.7/site-packages/gunicorn/app/base.py", line 67, in wsgi
    self.callable = self.load()
  File "/usr/local/lib/python3.7/site-packages/gunicorn/app/wsgiapp.py", line 58, in load
    return self.load_wsgiapp()
  File "/usr/local/lib/python3.7/site-packages/gunicorn/app/wsgiapp.py", line 48, in load_wsgiapp
    return util.import_app(self.app_uri)
  File "/usr/local/lib/python3.7/site-packages/gunicorn/util.py", line 359, in import_app
    mod = importlib.import_module(module)
  File "/usr/local/lib/python3.7/importlib/__init__.py", line 127, in import_module
    return _bootstrap._gcd_import(name[level:], package, level)
  File "<frozen importlib._bootstrap>", line 1006, in _gcd_import
  File "<frozen importlib._bootstrap>", line 983, in _find_and_load
  File "<frozen importlib._bootstrap>", line 965, in _find_and_load_unlocked
ModuleNotFoundError: No module named 'wsgi'
[2022-05-03 22:11:01 +0800] [111] [INFO] Worker exiting (pid: 111)
[2022-05-03 22:11:01 +0800] [108] [INFO] Shutting down: Master
[2022-05-03 22:11:01 +0800] [108] [INFO] Reason: Worker failed to boot.
[2022-05-03 22:11:19 +0800] [113] [INFO] Starting gunicorn 20.1.0
[2022-05-03 22:11:19 +0800] [113] [INFO] Listening at: http://0.0.0.0:8000 (113)
[2022-05-03 22:11:19 +0800] [113] [INFO] Using worker: gevent
[2022-05-03 22:11:19 +0800] [116] [INFO] Booting worker with pid: 116
[2022-05-03 22:11:19 +0800] [117] [INFO] Booting worker with pid: 117
[2022-05-03 22:11:19 +0800] [116] [ERROR] Exception in worker process
Traceback (most recent call last):
  File "/usr/local/lib/python3.7/site-packages/gunicorn/arbiter.py", line 589, in spawn_worker
    worker.init_process()
  File "/usr/local/lib/python3.7/site-packages/gunicorn/workers/ggevent.py", line 146, in init_process
    super().init_process()
  File "/usr/local/lib/python3.7/site-packages/gunicorn/workers/base.py", line 134, in init_process
    self.load_wsgi()
  File "/usr/local/lib/python3.7/site-packages/gunicorn/workers/base.py", line 146, in load_wsgi
    self.wsgi = self.app.wsgi()
  File "/usr/local/lib/python3.7/site-packages/gunicorn/app/base.py", line 67, in wsgi
    self.callable = self.load()
  File "/usr/local/lib/python3.7/site-packages/gunicorn/app/wsgiapp.py", line 58, in load
    return self.load_wsgiapp()
  File "/usr/local/lib/python3.7/site-packages/gunicorn/app/wsgiapp.py", line 48, in load_wsgiapp
    return util.import_app(self.app_uri)
  File "/usr/local/lib/python3.7/site-packages/gunicorn/util.py", line 359, in import_app
    mod = importlib.import_module(module)
  File "/usr/local/lib/python3.7/importlib/__init__.py", line 127, in import_module
    return _bootstrap._gcd_import(name[level:], package, level)
  File "<frozen importlib._bootstrap>", line 1006, in _gcd_import
  File "<frozen importlib._bootstrap>", line 983, in _find_and_load
  File "<frozen importlib._bootstrap>", line 965, in _find_and_load_unlocked
ModuleNotFoundError: No module named 'wsgi'
[2022-05-03 22:11:19 +0800] [116] [INFO] Worker exiting (pid: 116)
[2022-05-03 22:11:19 +0800] [117] [ERROR] Exception in worker process
Traceback (most recent call last):
  File "/usr/local/lib/python3.7/site-packages/gunicorn/arbiter.py", line 589, in spawn_worker
    worker.init_process()
  File "/usr/local/lib/python3.7/site-packages/gunicorn/workers/ggevent.py", line 146, in init_process
    super().init_process()
  File "/usr/local/lib/python3.7/site-packages/gunicorn/workers/base.py", line 134, in init_process
    self.load_wsgi()
  File "/usr/local/lib/python3.7/site-packages/gunicorn/workers/base.py", line 146, in load_wsgi
    self.wsgi = self.app.wsgi()
  File "/usr/local/lib/python3.7/site-packages/gunicorn/app/base.py", line 67, in wsgi
    self.callable = self.load()
  File "/usr/local/lib/python3.7/site-packages/gunicorn/app/wsgiapp.py", line 58, in load
    return self.load_wsgiapp()
  File "/usr/local/lib/python3.7/site-packages/gunicorn/app/wsgiapp.py", line 48, in load_wsgiapp
    return util.import_app(self.app_uri)
  File "/usr/local/lib/python3.7/site-packages/gunicorn/util.py", line 359, in import_app
    mod = importlib.import_module(module)
  File "/usr/local/lib/python3.7/importlib/__init__.py", line 127, in import_module
    return _bootstrap._gcd_import(name[level:], package, level)
  File "<frozen importlib._bootstrap>", line 1006, in _gcd_import
  File "<frozen importlib._bootstrap>", line 983, in _find_and_load
  File "<frozen importlib._bootstrap>", line 965, in _find_and_load_unlocked
ModuleNotFoundError: No module named 'wsgi'
[2022-05-03 22:11:19 +0800] [117] [INFO] Worker exiting (pid: 117)
Traceback (most recent call last):
  File "/usr/local/lib/python3.7/site-packages/gunicorn/arbiter.py", line 209, in run
    self.sleep()
  File "/usr/local/lib/python3.7/site-packages/gunicorn/arbiter.py", line 357, in sleep
    ready = select.select([self.PIPE[0]], [], [], 1.0)
  File "/usr/local/lib/python3.7/site-packages/gunicorn/arbiter.py", line 242, in handle_chld
    self.reap_workers()
  File "/usr/local/lib/python3.7/site-packages/gunicorn/arbiter.py", line 525, in reap_workers
    raise HaltServer(reason, self.WORKER_BOOT_ERROR)
gunicorn.errors.HaltServer: <HaltServer 'Worker failed to boot.' 3>

During handling of the above exception, another exception occurred:

Traceback (most recent call last):
  File "/usr/local/bin/gunicorn", line 8, in <module>
    sys.exit(run())
  File "/usr/local/lib/python3.7/site-packages/gunicorn/app/wsgiapp.py", line 67, in run
    WSGIApplication("%(prog)s [OPTIONS] [APP_MODULE]").run()
  File "/usr/local/lib/python3.7/site-packages/gunicorn/app/base.py", line 231, in run
    super().run()
  File "/usr/local/lib/python3.7/site-packages/gunicorn/app/base.py", line 72, in run
    Arbiter(self).run()
  File "/usr/local/lib/python3.7/site-packages/gunicorn/arbiter.py", line 229, in run
    self.halt(reason=inst.reason, exit_status=inst.exit_status)
  File "/usr/local/lib/python3.7/site-packages/gunicorn/arbiter.py", line 342, in halt
    self.stop()
  File "/usr/local/lib/python3.7/site-packages/gunicorn/arbiter.py", line 393, in stop
    time.sleep(0.1)
  File "/usr/local/lib/python3.7/site-packages/gunicorn/arbiter.py", line 242, in handle_chld
    self.reap_workers()
  File "/usr/local/lib/python3.7/site-packages/gunicorn/arbiter.py", line 525, in reap_workers
    raise HaltServer(reason, self.WORKER_BOOT_ERROR)
gunicorn.errors.HaltServer: <HaltServer 'Worker failed to boot.' 3>
[2022-05-03 22:11:38 +0800] [121] [INFO] Starting gunicorn 20.1.0
[2022-05-03 22:11:38 +0800] [121] [ERROR] Connection in use: ('0.0.0.0', 8000)
[2022-05-03 22:11:38 +0800] [121] [ERROR] Retrying in 1 second.
[2022-05-03 22:11:39 +0800] [121] [ERROR] Connection in use: ('0.0.0.0', 8000)
[2022-05-03 22:11:39 +0800] [121] [ERROR] Retrying in 1 second.
[2022-05-03 22:11:40 +0800] [121] [ERROR] Connection in use: ('0.0.0.0', 8000)
[2022-05-03 22:11:40 +0800] [121] [ERROR] Retrying in 1 second.
[2022-05-03 22:11:41 +0800] [121] [ERROR] Connection in use: ('0.0.0.0', 8000)
[2022-05-03 22:11:41 +0800] [121] [ERROR] Retrying in 1 second.
[2022-05-03 22:11:42 +0800] [121] [ERROR] Connection in use: ('0.0.0.0', 8000)
[2022-05-03 22:11:42 +0800] [121] [ERROR] Retrying in 1 second.
[2022-05-03 22:11:43 +0800] [121] [ERROR] Can't connect to ('0.0.0.0', 8000)
[2022-05-03 22:12:04 +0800] [127] [INFO] Starting gunicorn 20.1.0
[2022-05-03 22:12:04 +0800] [127] [INFO] Listening at: http://0.0.0.0:8000 (127)
[2022-05-03 22:12:04 +0800] [127] [INFO] Using worker: gevent
[2022-05-03 22:12:04 +0800] [130] [INFO] Booting worker with pid: 130
[2022-05-03 22:12:04 +0800] [131] [INFO] Booting worker with pid: 131
[2022-05-03 22:12:04 +0800] [130] [ERROR] Exception in worker process
Traceback (most recent call last):
  File "/usr/local/lib/python3.7/site-packages/gunicorn/arbiter.py", line 589, in spawn_worker
    worker.init_process()
  File "/usr/local/lib/python3.7/site-packages/gunicorn/workers/ggevent.py", line 146, in init_process
    super().init_process()
  File "/usr/local/lib/python3.7/site-packages/gunicorn/workers/base.py", line 134, in init_process
    self.load_wsgi()
  File "/usr/local/lib/python3.7/site-packages/gunicorn/workers/base.py", line 146, in load_wsgi
    self.wsgi = self.app.wsgi()
  File "/usr/local/lib/python3.7/site-packages/gunicorn/app/base.py", line 67, in wsgi
    self.callable = self.load()
  File "/usr/local/lib/python3.7/site-packages/gunicorn/app/wsgiapp.py", line 58, in load
    return self.load_wsgiapp()
  File "/usr/local/lib/python3.7/site-packages/gunicorn/app/wsgiapp.py", line 48, in load_wsgiapp
    return util.import_app(self.app_uri)
  File "/usr/local/lib/python3.7/site-packages/gunicorn/util.py", line 359, in import_app
    mod = importlib.import_module(module)
  File "/usr/local/lib/python3.7/importlib/__init__.py", line 127, in import_module
    return _bootstrap._gcd_import(name[level:], package, level)
  File "<frozen importlib._bootstrap>", line 1006, in _gcd_import
  File "<frozen importlib._bootstrap>", line 983, in _find_and_load
  File "<frozen importlib._bootstrap>", line 965, in _find_and_load_unlocked
ModuleNotFoundError: No module named 'wsgi'
[2022-05-03 22:12:04 +0800] [130] [INFO] Worker exiting (pid: 130)
[2022-05-03 22:12:04 +0800] [131] [ERROR] Exception in worker process
Traceback (most recent call last):
  File "/usr/local/lib/python3.7/site-packages/gunicorn/arbiter.py", line 589, in spawn_worker
    worker.init_process()
  File "/usr/local/lib/python3.7/site-packages/gunicorn/workers/ggevent.py", line 146, in init_process
    super().init_process()
  File "/usr/local/lib/python3.7/site-packages/gunicorn/workers/base.py", line 134, in init_process
    self.load_wsgi()
  File "/usr/local/lib/python3.7/site-packages/gunicorn/workers/base.py", line 146, in load_wsgi
    self.wsgi = self.app.wsgi()
  File "/usr/local/lib/python3.7/site-packages/gunicorn/app/base.py", line 67, in wsgi
    self.callable = self.load()
  File "/usr/local/lib/python3.7/site-packages/gunicorn/app/wsgiapp.py", line 58, in load
    return self.load_wsgiapp()
  File "/usr/local/lib/python3.7/site-packages/gunicorn/app/wsgiapp.py", line 48, in load_wsgiapp
    return util.import_app(self.app_uri)
  File "/usr/local/lib/python3.7/site-packages/gunicorn/util.py", line 359, in import_app
    mod = importlib.import_module(module)
  File "/usr/local/lib/python3.7/importlib/__init__.py", line 127, in import_module
    return _bootstrap._gcd_import(name[level:], package, level)
  File "<frozen importlib._bootstrap>", line 1006, in _gcd_import
  File "<frozen importlib._bootstrap>", line 983, in _find_and_load
  File "<frozen importlib._bootstrap>", line 965, in _find_and_load_unlocked
ModuleNotFoundError: No module named 'wsgi'
[2022-05-03 22:12:04 +0800] [131] [INFO] Worker exiting (pid: 131)
Traceback (most recent call last):
  File "/usr/local/lib/python3.7/site-packages/gunicorn/arbiter.py", line 202, in run
    self.manage_workers()
  File "/usr/local/lib/python3.7/site-packages/gunicorn/arbiter.py", line 551, in manage_workers
    self.spawn_workers()
  File "/usr/local/lib/python3.7/site-packages/gunicorn/arbiter.py", line 623, in spawn_workers
    time.sleep(0.1 * random.random())
  File "/usr/local/lib/python3.7/site-packages/gunicorn/arbiter.py", line 242, in handle_chld
    self.reap_workers()
  File "/usr/local/lib/python3.7/site-packages/gunicorn/arbiter.py", line 525, in reap_workers
    raise HaltServer(reason, self.WORKER_BOOT_ERROR)
gunicorn.errors.HaltServer: <HaltServer 'Worker failed to boot.' 3>

During handling of the above exception, another exception occurred:

Traceback (most recent call last):
  File "/usr/local/bin/gunicorn", line 8, in <module>
    sys.exit(run())
  File "/usr/local/lib/python3.7/site-packages/gunicorn/app/wsgiapp.py", line 67, in run
    WSGIApplication("%(prog)s [OPTIONS] [APP_MODULE]").run()
  File "/usr/local/lib/python3.7/site-packages/gunicorn/app/base.py", line 231, in run
    super().run()
  File "/usr/local/lib/python3.7/site-packages/gunicorn/app/base.py", line 72, in run
    Arbiter(self).run()
  File "/usr/local/lib/python3.7/site-packages/gunicorn/arbiter.py", line 229, in run
    self.halt(reason=inst.reason, exit_status=inst.exit_status)
  File "/usr/local/lib/python3.7/site-packages/gunicorn/arbiter.py", line 342, in halt
    self.stop()
  File "/usr/local/lib/python3.7/site-packages/gunicorn/arbiter.py", line 393, in stop
    time.sleep(0.1)
  File "/usr/local/lib/python3.7/site-packages/gunicorn/arbiter.py", line 242, in handle_chld
    self.reap_workers()
  File "/usr/local/lib/python3.7/site-packages/gunicorn/arbiter.py", line 525, in reap_workers
    raise HaltServer(reason, self.WORKER_BOOT_ERROR)
gunicorn.errors.HaltServer: <HaltServer 'Worker failed to boot.' 3>
[2022-05-03 22:12:26 +0800] [133] [INFO] Starting gunicorn 20.1.0
[2022-05-03 22:12:26 +0800] [133] [INFO] Listening at: http://0.0.0.0:8000 (133)
[2022-05-03 22:12:26 +0800] [133] [INFO] Using worker: gevent
[2022-05-03 22:12:26 +0800] [136] [INFO] Booting worker with pid: 136
[2022-05-03 22:12:26 +0800] [137] [INFO] Booting worker with pid: 137
[2022-05-03 22:12:26 +0800] [136] [ERROR] Exception in worker process
Traceback (most recent call last):
  File "/usr/local/lib/python3.7/site-packages/gunicorn/arbiter.py", line 589, in spawn_worker
    worker.init_process()
  File "/usr/local/lib/python3.7/site-packages/gunicorn/workers/ggevent.py", line 146, in init_process
    super().init_process()
  File "/usr/local/lib/python3.7/site-packages/gunicorn/workers/base.py", line 134, in init_process
    self.load_wsgi()
  File "/usr/local/lib/python3.7/site-packages/gunicorn/workers/base.py", line 146, in load_wsgi
    self.wsgi = self.app.wsgi()
  File "/usr/local/lib/python3.7/site-packages/gunicorn/app/base.py", line 67, in wsgi
    self.callable = self.load()
  File "/usr/local/lib/python3.7/site-packages/gunicorn/app/wsgiapp.py", line 58, in load
    return self.load_wsgiapp()
  File "/usr/local/lib/python3.7/site-packages/gunicorn/app/wsgiapp.py", line 48, in load_wsgiapp
    return util.import_app(self.app_uri)
  File "/usr/local/lib/python3.7/site-packages/gunicorn/util.py", line 359, in import_app
    mod = importlib.import_module(module)
  File "/usr/local/lib/python3.7/importlib/__init__.py", line 127, in import_module
    return _bootstrap._gcd_import(name[level:], package, level)
  File "<frozen importlib._bootstrap>", line 1006, in _gcd_import
  File "<frozen importlib._bootstrap>", line 983, in _find_and_load
  File "<frozen importlib._bootstrap>", line 965, in _find_and_load_unlocked
ModuleNotFoundError: No module named 'wsgi'
[2022-05-03 22:12:26 +0800] [136] [INFO] Worker exiting (pid: 136)
[2022-05-03 22:12:26 +0800] [137] [ERROR] Exception in worker process
Traceback (most recent call last):
  File "/usr/local/lib/python3.7/site-packages/gunicorn/arbiter.py", line 589, in spawn_worker
    worker.init_process()
  File "/usr/local/lib/python3.7/site-packages/gunicorn/workers/ggevent.py", line 146, in init_process
    super().init_process()
  File "/usr/local/lib/python3.7/site-packages/gunicorn/workers/base.py", line 134, in init_process
    self.load_wsgi()
  File "/usr/local/lib/python3.7/site-packages/gunicorn/workers/base.py", line 146, in load_wsgi
    self.wsgi = self.app.wsgi()
  File "/usr/local/lib/python3.7/site-packages/gunicorn/app/base.py", line 67, in wsgi
    self.callable = self.load()
  File "/usr/local/lib/python3.7/site-packages/gunicorn/app/wsgiapp.py", line 58, in load
    return self.load_wsgiapp()
  File "/usr/local/lib/python3.7/site-packages/gunicorn/app/wsgiapp.py", line 48, in load_wsgiapp
    return util.import_app(self.app_uri)
  File "/usr/local/lib/python3.7/site-packages/gunicorn/util.py", line 359, in import_app
    mod = importlib.import_module(module)
  File "/usr/local/lib/python3.7/importlib/__init__.py", line 127, in import_module
    return _bootstrap._gcd_import(name[level:], package, level)
  File "<frozen importlib._bootstrap>", line 1006, in _gcd_import
  File "<frozen importlib._bootstrap>", line 983, in _find_and_load
  File "<frozen importlib._bootstrap>", line 965, in _find_and_load_unlocked
ModuleNotFoundError: No module named 'wsgi'
[2022-05-03 22:12:26 +0800] [137] [INFO] Worker exiting (pid: 137)
Traceback (most recent call last):
  File "/usr/local/lib/python3.7/site-packages/gunicorn/arbiter.py", line 202, in run
    self.manage_workers()
  File "/usr/local/lib/python3.7/site-packages/gunicorn/arbiter.py", line 551, in manage_workers
    self.spawn_workers()
  File "/usr/local/lib/python3.7/site-packages/gunicorn/arbiter.py", line 623, in spawn_workers
    time.sleep(0.1 * random.random())
  File "/usr/local/lib/python3.7/site-packages/gunicorn/arbiter.py", line 242, in handle_chld
    self.reap_workers()
  File "/usr/local/lib/python3.7/site-packages/gunicorn/arbiter.py", line 525, in reap_workers
    raise HaltServer(reason, self.WORKER_BOOT_ERROR)
gunicorn.errors.HaltServer: <HaltServer 'Worker failed to boot.' 3>

During handling of the above exception, another exception occurred:

Traceback (most recent call last):
  File "/usr/local/bin/gunicorn", line 8, in <module>
    sys.exit(run())
  File "/usr/local/lib/python3.7/site-packages/gunicorn/app/wsgiapp.py", line 67, in run
    WSGIApplication("%(prog)s [OPTIONS] [APP_MODULE]").run()
  File "/usr/local/lib/python3.7/site-packages/gunicorn/app/base.py", line 231, in run
    super().run()
  File "/usr/local/lib/python3.7/site-packages/gunicorn/app/base.py", line 72, in run
    Arbiter(self).run()
  File "/usr/local/lib/python3.7/site-packages/gunicorn/arbiter.py", line 229, in run
    self.halt(reason=inst.reason, exit_status=inst.exit_status)
  File "/usr/local/lib/python3.7/site-packages/gunicorn/arbiter.py", line 342, in halt
    self.stop()
  File "/usr/local/lib/python3.7/site-packages/gunicorn/arbiter.py", line 393, in stop
    time.sleep(0.1)
  File "/usr/local/lib/python3.7/site-packages/gunicorn/arbiter.py", line 242, in handle_chld
    self.reap_workers()
  File "/usr/local/lib/python3.7/site-packages/gunicorn/arbiter.py", line 525, in reap_workers
    raise HaltServer(reason, self.WORKER_BOOT_ERROR)
gunicorn.errors.HaltServer: <HaltServer 'Worker failed to boot.' 3>
[2022-05-03 22:12:48 +0800] [138] [INFO] Starting gunicorn 20.1.0
[2022-05-03 22:12:48 +0800] [138] [INFO] Listening at: http://0.0.0.0:8000 (138)
[2022-05-03 22:12:48 +0800] [138] [INFO] Using worker: gevent
[2022-05-03 22:12:48 +0800] [141] [INFO] Booting worker with pid: 141
[2022-05-03 22:12:48 +0800] [142] [INFO] Booting worker with pid: 142
[2022-05-03 22:12:48 +0800] [141] [ERROR] Exception in worker process
Traceback (most recent call last):
  File "/usr/local/lib/python3.7/site-packages/gunicorn/arbiter.py", line 589, in spawn_worker
    worker.init_process()
  File "/usr/local/lib/python3.7/site-packages/gunicorn/workers/ggevent.py", line 146, in init_process
    super().init_process()
  File "/usr/local/lib/python3.7/site-packages/gunicorn/workers/base.py", line 134, in init_process
    self.load_wsgi()
  File "/usr/local/lib/python3.7/site-packages/gunicorn/workers/base.py", line 146, in load_wsgi
    self.wsgi = self.app.wsgi()
  File "/usr/local/lib/python3.7/site-packages/gunicorn/app/base.py", line 67, in wsgi
    self.callable = self.load()
  File "/usr/local/lib/python3.7/site-packages/gunicorn/app/wsgiapp.py", line 58, in load
    return self.load_wsgiapp()
  File "/usr/local/lib/python3.7/site-packages/gunicorn/app/wsgiapp.py", line 48, in load_wsgiapp
    return util.import_app(self.app_uri)
  File "/usr/local/lib/python3.7/site-packages/gunicorn/util.py", line 359, in import_app
    mod = importlib.import_module(module)
  File "/usr/local/lib/python3.7/importlib/__init__.py", line 127, in import_module
    return _bootstrap._gcd_import(name[level:], package, level)
  File "<frozen importlib._bootstrap>", line 1006, in _gcd_import
  File "<frozen importlib._bootstrap>", line 983, in _find_and_load
  File "<frozen importlib._bootstrap>", line 965, in _find_and_load_unlocked
ModuleNotFoundError: No module named 'wsgi'
[2022-05-03 22:12:48 +0800] [141] [INFO] Worker exiting (pid: 141)
[2022-05-03 22:12:48 +0800] [142] [ERROR] Exception in worker process
Traceback (most recent call last):
  File "/usr/local/lib/python3.7/site-packages/gunicorn/arbiter.py", line 589, in spawn_worker
    worker.init_process()
  File "/usr/local/lib/python3.7/site-packages/gunicorn/workers/ggevent.py", line 146, in init_process
    super().init_process()
  File "/usr/local/lib/python3.7/site-packages/gunicorn/workers/base.py", line 134, in init_process
    self.load_wsgi()
  File "/usr/local/lib/python3.7/site-packages/gunicorn/workers/base.py", line 146, in load_wsgi
    self.wsgi = self.app.wsgi()
  File "/usr/local/lib/python3.7/site-packages/gunicorn/app/base.py", line 67, in wsgi
    self.callable = self.load()
  File "/usr/local/lib/python3.7/site-packages/gunicorn/app/wsgiapp.py", line 58, in load
    return self.load_wsgiapp()
  File "/usr/local/lib/python3.7/site-packages/gunicorn/app/wsgiapp.py", line 48, in load_wsgiapp
    return util.import_app(self.app_uri)
  File "/usr/local/lib/python3.7/site-packages/gunicorn/util.py", line 359, in import_app
    mod = importlib.import_module(module)
  File "/usr/local/lib/python3.7/importlib/__init__.py", line 127, in import_module
    return _bootstrap._gcd_import(name[level:], package, level)
  File "<frozen importlib._bootstrap>", line 1006, in _gcd_import
  File "<frozen importlib._bootstrap>", line 983, in _find_and_load
  File "<frozen importlib._bootstrap>", line 965, in _find_and_load_unlocked
ModuleNotFoundError: No module named 'wsgi'
[2022-05-03 22:12:48 +0800] [142] [INFO] Worker exiting (pid: 142)
[2022-05-03 22:12:48 +0800] [138] [WARNING] Worker with pid 142 was terminated due to signal 15
[2022-05-03 22:12:48 +0800] [138] [INFO] Shutting down: Master
[2022-05-03 22:12:48 +0800] [138] [INFO] Reason: Worker failed to boot.
[2022-05-03 22:13:11 +0800] [143] [INFO] Starting gunicorn 20.1.0
[2022-05-03 22:13:11 +0800] [143] [INFO] Listening at: http://0.0.0.0:8000 (143)
[2022-05-03 22:13:11 +0800] [143] [INFO] Using worker: gevent
[2022-05-03 22:13:11 +0800] [146] [INFO] Booting worker with pid: 146
[2022-05-03 22:13:11 +0800] [147] [INFO] Booting worker with pid: 147
[2022-05-03 22:13:11 +0800] [146] [ERROR] Exception in worker process
Traceback (most recent call last):
  File "/usr/local/lib/python3.7/site-packages/gunicorn/arbiter.py", line 589, in spawn_worker
    worker.init_process()
  File "/usr/local/lib/python3.7/site-packages/gunicorn/workers/ggevent.py", line 146, in init_process
    super().init_process()
  File "/usr/local/lib/python3.7/site-packages/gunicorn/workers/base.py", line 134, in init_process
    self.load_wsgi()
  File "/usr/local/lib/python3.7/site-packages/gunicorn/workers/base.py", line 146, in load_wsgi
    self.wsgi = self.app.wsgi()
  File "/usr/local/lib/python3.7/site-packages/gunicorn/app/base.py", line 67, in wsgi
    self.callable = self.load()
  File "/usr/local/lib/python3.7/site-packages/gunicorn/app/wsgiapp.py", line 58, in load
    return self.load_wsgiapp()
  File "/usr/local/lib/python3.7/site-packages/gunicorn/app/wsgiapp.py", line 48, in load_wsgiapp
    return util.import_app(self.app_uri)
  File "/usr/local/lib/python3.7/site-packages/gunicorn/util.py", line 359, in import_app
    mod = importlib.import_module(module)
  File "/usr/local/lib/python3.7/importlib/__init__.py", line 127, in import_module
    return _bootstrap._gcd_import(name[level:], package, level)
  File "<frozen importlib._bootstrap>", line 1006, in _gcd_import
  File "<frozen importlib._bootstrap>", line 983, in _find_and_load
  File "<frozen importlib._bootstrap>", line 965, in _find_and_load_unlocked
ModuleNotFoundError: No module named 'wsgi'
[2022-05-03 22:13:11 +0800] [146] [INFO] Worker exiting (pid: 146)
[2022-05-03 22:13:12 +0800] [147] [ERROR] Exception in worker process
Traceback (most recent call last):
  File "/usr/local/lib/python3.7/site-packages/gunicorn/arbiter.py", line 589, in spawn_worker
    worker.init_process()
  File "/usr/local/lib/python3.7/site-packages/gunicorn/workers/ggevent.py", line 146, in init_process
    super().init_process()
  File "/usr/local/lib/python3.7/site-packages/gunicorn/workers/base.py", line 134, in init_process
    self.load_wsgi()
  File "/usr/local/lib/python3.7/site-packages/gunicorn/workers/base.py", line 146, in load_wsgi
    self.wsgi = self.app.wsgi()
  File "/usr/local/lib/python3.7/site-packages/gunicorn/app/base.py", line 67, in wsgi
    self.callable = self.load()
  File "/usr/local/lib/python3.7/site-packages/gunicorn/app/wsgiapp.py", line 58, in load
    return self.load_wsgiapp()
  File "/usr/local/lib/python3.7/site-packages/gunicorn/app/wsgiapp.py", line 48, in load_wsgiapp
    return util.import_app(self.app_uri)
  File "/usr/local/lib/python3.7/site-packages/gunicorn/util.py", line 359, in import_app
    mod = importlib.import_module(module)
  File "/usr/local/lib/python3.7/importlib/__init__.py", line 127, in import_module
    return _bootstrap._gcd_import(name[level:], package, level)
  File "<frozen importlib._bootstrap>", line 1006, in _gcd_import
  File "<frozen importlib._bootstrap>", line 983, in _find_and_load
  File "<frozen importlib._bootstrap>", line 965, in _find_and_load_unlocked
ModuleNotFoundError: No module named 'wsgi'
[2022-05-03 22:13:12 +0800] [147] [INFO] Worker exiting (pid: 147)
[2022-05-03 22:13:12 +0800] [143] [WARNING] Worker with pid 147 was terminated due to signal 15
[2022-05-03 22:13:12 +0800] [143] [INFO] Shutting down: Master
[2022-05-03 22:13:12 +0800] [143] [INFO] Reason: Worker failed to boot.
[2022-05-03 22:13:36 +0800] [148] [INFO] Starting gunicorn 20.1.0
[2022-05-03 22:13:36 +0800] [148] [INFO] Listening at: http://0.0.0.0:8000 (148)
[2022-05-03 22:13:36 +0800] [148] [INFO] Using worker: gevent
[2022-05-03 22:13:36 +0800] [151] [INFO] Booting worker with pid: 151
[2022-05-03 22:13:36 +0800] [152] [INFO] Booting worker with pid: 152
[2022-05-03 22:13:36 +0800] [151] [ERROR] Exception in worker process
Traceback (most recent call last):
  File "/usr/local/lib/python3.7/site-packages/gunicorn/arbiter.py", line 589, in spawn_worker
    worker.init_process()
  File "/usr/local/lib/python3.7/site-packages/gunicorn/workers/ggevent.py", line 146, in init_process
    super().init_process()
  File "/usr/local/lib/python3.7/site-packages/gunicorn/workers/base.py", line 134, in init_process
    self.load_wsgi()
  File "/usr/local/lib/python3.7/site-packages/gunicorn/workers/base.py", line 146, in load_wsgi
    self.wsgi = self.app.wsgi()
  File "/usr/local/lib/python3.7/site-packages/gunicorn/app/base.py", line 67, in wsgi
    self.callable = self.load()
  File "/usr/local/lib/python3.7/site-packages/gunicorn/app/wsgiapp.py", line 58, in load
    return self.load_wsgiapp()
  File "/usr/local/lib/python3.7/site-packages/gunicorn/app/wsgiapp.py", line 48, in load_wsgiapp
    return util.import_app(self.app_uri)
  File "/usr/local/lib/python3.7/site-packages/gunicorn/util.py", line 359, in import_app
    mod = importlib.import_module(module)
  File "/usr/local/lib/python3.7/importlib/__init__.py", line 127, in import_module
    return _bootstrap._gcd_import(name[level:], package, level)
  File "<frozen importlib._bootstrap>", line 1006, in _gcd_import
  File "<frozen importlib._bootstrap>", line 983, in _find_and_load
  File "<frozen importlib._bootstrap>", line 965, in _find_and_load_unlocked
ModuleNotFoundError: No module named 'wsgi'
[2022-05-03 22:13:36 +0800] [151] [INFO] Worker exiting (pid: 151)
[2022-05-03 22:13:36 +0800] [152] [ERROR] Exception in worker process
Traceback (most recent call last):
  File "/usr/local/lib/python3.7/site-packages/gunicorn/arbiter.py", line 589, in spawn_worker
    worker.init_process()
  File "/usr/local/lib/python3.7/site-packages/gunicorn/workers/ggevent.py", line 146, in init_process
    super().init_process()
  File "/usr/local/lib/python3.7/site-packages/gunicorn/workers/base.py", line 134, in init_process
    self.load_wsgi()
  File "/usr/local/lib/python3.7/site-packages/gunicorn/workers/base.py", line 146, in load_wsgi
    self.wsgi = self.app.wsgi()
  File "/usr/local/lib/python3.7/site-packages/gunicorn/app/base.py", line 67, in wsgi
    self.callable = self.load()
  File "/usr/local/lib/python3.7/site-packages/gunicorn/app/wsgiapp.py", line 58, in load
    return self.load_wsgiapp()
  File "/usr/local/lib/python3.7/site-packages/gunicorn/app/wsgiapp.py", line 48, in load_wsgiapp
    return util.import_app(self.app_uri)
  File "/usr/local/lib/python3.7/site-packages/gunicorn/util.py", line 359, in import_app
    mod = importlib.import_module(module)
  File "/usr/local/lib/python3.7/importlib/__init__.py", line 127, in import_module
    return _bootstrap._gcd_import(name[level:], package, level)
  File "<frozen importlib._bootstrap>", line 1006, in _gcd_import
  File "<frozen importlib._bootstrap>", line 983, in _find_and_load
  File "<frozen importlib._bootstrap>", line 965, in _find_and_load_unlocked
ModuleNotFoundError: No module named 'wsgi'
[2022-05-03 22:13:36 +0800] [152] [INFO] Worker exiting (pid: 152)
Traceback (most recent call last):
  File "/usr/local/lib/python3.7/site-packages/gunicorn/arbiter.py", line 202, in run
    self.manage_workers()
  File "/usr/local/lib/python3.7/site-packages/gunicorn/arbiter.py", line 551, in manage_workers
    self.spawn_workers()
  File "/usr/local/lib/python3.7/site-packages/gunicorn/arbiter.py", line 623, in spawn_workers
    time.sleep(0.1 * random.random())
  File "/usr/local/lib/python3.7/site-packages/gunicorn/arbiter.py", line 242, in handle_chld
    self.reap_workers()
  File "/usr/local/lib/python3.7/site-packages/gunicorn/arbiter.py", line 525, in reap_workers
    raise HaltServer(reason, self.WORKER_BOOT_ERROR)
gunicorn.errors.HaltServer: <HaltServer 'Worker failed to boot.' 3>

During handling of the above exception, another exception occurred:

Traceback (most recent call last):
  File "/usr/local/bin/gunicorn", line 8, in <module>
    sys.exit(run())
  File "/usr/local/lib/python3.7/site-packages/gunicorn/app/wsgiapp.py", line 67, in run
    WSGIApplication("%(prog)s [OPTIONS] [APP_MODULE]").run()
  File "/usr/local/lib/python3.7/site-packages/gunicorn/app/base.py", line 231, in run
    super().run()
  File "/usr/local/lib/python3.7/site-packages/gunicorn/app/base.py", line 72, in run
    Arbiter(self).run()
  File "/usr/local/lib/python3.7/site-packages/gunicorn/arbiter.py", line 229, in run
    self.halt(reason=inst.reason, exit_status=inst.exit_status)
  File "/usr/local/lib/python3.7/site-packages/gunicorn/arbiter.py", line 342, in halt
    self.stop()
  File "/usr/local/lib/python3.7/site-packages/gunicorn/arbiter.py", line 393, in stop
    time.sleep(0.1)
  File "/usr/local/lib/python3.7/site-packages/gunicorn/arbiter.py", line 242, in handle_chld
    self.reap_workers()
  File "/usr/local/lib/python3.7/site-packages/gunicorn/arbiter.py", line 525, in reap_workers
    raise HaltServer(reason, self.WORKER_BOOT_ERROR)
gunicorn.errors.HaltServer: <HaltServer 'Worker failed to boot.' 3>
[2022-05-03 22:14:01 +0800] [153] [INFO] Starting gunicorn 20.1.0
[2022-05-03 22:14:01 +0800] [153] [INFO] Listening at: http://0.0.0.0:8000 (153)
[2022-05-03 22:14:01 +0800] [153] [INFO] Using worker: gevent
[2022-05-03 22:14:01 +0800] [156] [INFO] Booting worker with pid: 156
[2022-05-03 22:14:01 +0800] [157] [INFO] Booting worker with pid: 157
[2022-05-03 22:14:01 +0800] [156] [ERROR] Exception in worker process
Traceback (most recent call last):
  File "/usr/local/lib/python3.7/site-packages/gunicorn/arbiter.py", line 589, in spawn_worker
    worker.init_process()
  File "/usr/local/lib/python3.7/site-packages/gunicorn/workers/ggevent.py", line 146, in init_process
    super().init_process()
  File "/usr/local/lib/python3.7/site-packages/gunicorn/workers/base.py", line 134, in init_process
    self.load_wsgi()
  File "/usr/local/lib/python3.7/site-packages/gunicorn/workers/base.py", line 146, in load_wsgi
    self.wsgi = self.app.wsgi()
  File "/usr/local/lib/python3.7/site-packages/gunicorn/app/base.py", line 67, in wsgi
    self.callable = self.load()
  File "/usr/local/lib/python3.7/site-packages/gunicorn/app/wsgiapp.py", line 58, in load
    return self.load_wsgiapp()
  File "/usr/local/lib/python3.7/site-packages/gunicorn/app/wsgiapp.py", line 48, in load_wsgiapp
    return util.import_app(self.app_uri)
  File "/usr/local/lib/python3.7/site-packages/gunicorn/util.py", line 359, in import_app
    mod = importlib.import_module(module)
  File "/usr/local/lib/python3.7/importlib/__init__.py", line 127, in import_module
    return _bootstrap._gcd_import(name[level:], package, level)
  File "<frozen importlib._bootstrap>", line 1006, in _gcd_import
  File "<frozen importlib._bootstrap>", line 983, in _find_and_load
  File "<frozen importlib._bootstrap>", line 965, in _find_and_load_unlocked
ModuleNotFoundError: No module named 'wsgi'
[2022-05-03 22:14:01 +0800] [156] [INFO] Worker exiting (pid: 156)
[2022-05-03 22:14:01 +0800] [157] [ERROR] Exception in worker process
Traceback (most recent call last):
  File "/usr/local/lib/python3.7/site-packages/gunicorn/arbiter.py", line 589, in spawn_worker
    worker.init_process()
  File "/usr/local/lib/python3.7/site-packages/gunicorn/workers/ggevent.py", line 146, in init_process
    super().init_process()
  File "/usr/local/lib/python3.7/site-packages/gunicorn/workers/base.py", line 134, in init_process
    self.load_wsgi()
  File "/usr/local/lib/python3.7/site-packages/gunicorn/workers/base.py", line 146, in load_wsgi
    self.wsgi = self.app.wsgi()
  File "/usr/local/lib/python3.7/site-packages/gunicorn/app/base.py", line 67, in wsgi
    self.callable = self.load()
  File "/usr/local/lib/python3.7/site-packages/gunicorn/app/wsgiapp.py", line 58, in load
    return self.load_wsgiapp()
  File "/usr/local/lib/python3.7/site-packages/gunicorn/app/wsgiapp.py", line 48, in load_wsgiapp
    return util.import_app(self.app_uri)
  File "/usr/local/lib/python3.7/site-packages/gunicorn/util.py", line 359, in import_app
    mod = importlib.import_module(module)
  File "/usr/local/lib/python3.7/importlib/__init__.py", line 127, in import_module
    return _bootstrap._gcd_import(name[level:], package, level)
  File "<frozen importlib._bootstrap>", line 1006, in _gcd_import
  File "<frozen importlib._bootstrap>", line 983, in _find_and_load
  File "<frozen importlib._bootstrap>", line 965, in _find_and_load_unlocked
ModuleNotFoundError: No module named 'wsgi'
[2022-05-03 22:14:01 +0800] [157] [INFO] Worker exiting (pid: 157)
Traceback (most recent call last):
  File "/usr/local/lib/python3.7/site-packages/gunicorn/arbiter.py", line 202, in run
    self.manage_workers()
  File "/usr/local/lib/python3.7/site-packages/gunicorn/arbiter.py", line 551, in manage_workers
    self.spawn_workers()
  File "/usr/local/lib/python3.7/site-packages/gunicorn/arbiter.py", line 623, in spawn_workers
    time.sleep(0.1 * random.random())
  File "/usr/local/lib/python3.7/site-packages/gunicorn/arbiter.py", line 242, in handle_chld
    self.reap_workers()
  File "/usr/local/lib/python3.7/site-packages/gunicorn/arbiter.py", line 525, in reap_workers
    raise HaltServer(reason, self.WORKER_BOOT_ERROR)
gunicorn.errors.HaltServer: <HaltServer 'Worker failed to boot.' 3>

During handling of the above exception, another exception occurred:

Traceback (most recent call last):
  File "/usr/local/bin/gunicorn", line 8, in <module>
    sys.exit(run())
  File "/usr/local/lib/python3.7/site-packages/gunicorn/app/wsgiapp.py", line 67, in run
    WSGIApplication("%(prog)s [OPTIONS] [APP_MODULE]").run()
  File "/usr/local/lib/python3.7/site-packages/gunicorn/app/base.py", line 231, in run
    super().run()
  File "/usr/local/lib/python3.7/site-packages/gunicorn/app/base.py", line 72, in run
    Arbiter(self).run()
  File "/usr/local/lib/python3.7/site-packages/gunicorn/arbiter.py", line 229, in run
    self.halt(reason=inst.reason, exit_status=inst.exit_status)
  File "/usr/local/lib/python3.7/site-packages/gunicorn/arbiter.py", line 342, in halt
    self.stop()
  File "/usr/local/lib/python3.7/site-packages/gunicorn/arbiter.py", line 393, in stop
    time.sleep(0.1)
  File "/usr/local/lib/python3.7/site-packages/gunicorn/arbiter.py", line 242, in handle_chld
    self.reap_workers()
  File "/usr/local/lib/python3.7/site-packages/gunicorn/arbiter.py", line 525, in reap_workers
    raise HaltServer(reason, self.WORKER_BOOT_ERROR)
gunicorn.errors.HaltServer: <HaltServer 'Worker failed to boot.' 3>
[2022-05-03 22:14:32 +0800] [10] [INFO] Starting gunicorn 20.1.0
[2022-05-03 22:14:32 +0800] [10] [INFO] Listening at: http://0.0.0.0:8000 (10)
[2022-05-03 22:14:32 +0800] [10] [INFO] Using worker: gevent
[2022-05-03 22:14:32 +0800] [13] [INFO] Booting worker with pid: 13
[2022-05-03 22:14:32 +0800] [14] [INFO] Booting worker with pid: 14
[2022-05-03 22:17:46 +0800] [10] [INFO] Handling signal: term
[2022-05-03 22:17:46 +0800] [14] [INFO] Worker exiting (pid: 14)
[2022-05-03 22:17:46 +0800] [13] [INFO] Worker exiting (pid: 13)
[2022-05-03 22:17:46 +0800] [10] [INFO] Shutting down: Master
